[2024-12-24T18:49:01.465+0000] {local_task_job_runner.py:120} INFO - ::group::Pre task execution logs
[2024-12-24T18:49:01.497+0000] {taskinstance.py:2076} INFO - Dependencies all met for dep_context=non-requeueable deps ti=<TaskInstance: pipeline_batch_visualize.start manual__2024-12-24T18:48:59.634517+00:00 [queued]>
[2024-12-24T18:49:01.510+0000] {taskinstance.py:2076} INFO - Dependencies all met for dep_context=requeueable deps ti=<TaskInstance: pipeline_batch_visualize.start manual__2024-12-24T18:48:59.634517+00:00 [queued]>
[2024-12-24T18:49:01.511+0000] {taskinstance.py:2306} INFO - Starting attempt 1 of 1
[2024-12-24T18:49:01.534+0000] {taskinstance.py:2330} INFO - Executing <Task(PythonOperator): start> on 2024-12-24 18:48:59.634517+00:00
[2024-12-24T18:49:01.544+0000] {standard_task_runner.py:63} INFO - Started process 9000 to run task
[2024-12-24T18:49:01.548+0000] {standard_task_runner.py:90} INFO - Running: ['***', 'tasks', 'run', 'pipeline_batch_visualize', 'start', 'manual__2024-12-24T18:48:59.634517+00:00', '--job-id', '340', '--raw', '--subdir', 'DAGS_FOLDER/pipeline_batch_visualize.py', '--cfg-path', '/tmp/tmp5or694pr']
[2024-12-24T18:49:01.552+0000] {standard_task_runner.py:91} INFO - Job 340: Subtask start
[2024-12-24T18:49:01.612+0000] {task_command.py:426} INFO - Running <TaskInstance: pipeline_batch_visualize.start manual__2024-12-24T18:48:59.634517+00:00 [running]> on host 0b4a5bf62610
[2024-12-24T18:49:01.727+0000] {taskinstance.py:2648} INFO - Exporting env vars: AIRFLOW_CTX_DAG_OWNER='***' AIRFLOW_CTX_DAG_ID='pipeline_batch_visualize' AIRFLOW_CTX_TASK_ID='start' AIRFLOW_CTX_EXECUTION_DATE='2024-12-24T18:48:59.634517+00:00' AIRFLOW_CTX_TRY_NUMBER='1' AIRFLOW_CTX_DAG_RUN_ID='manual__2024-12-24T18:48:59.634517+00:00'
[2024-12-24T18:49:01.729+0000] {taskinstance.py:430} INFO - ::endgroup::
[2024-12-24T18:49:01.744+0000] {logging_mixin.py:188} WARNING - --- Logging error ---
[2024-12-24T18:49:01.745+0000] {logging_mixin.py:188} WARNING - Traceback (most recent call last):
[2024-12-24T18:49:01.746+0000] {logging_mixin.py:188} WARNING -   File "/usr/local/lib/python3.12/logging/__init__.py", line 1160, in emit
    msg = self.format(record)
          ^^^^^^^^^^^^^^^^^^^
[2024-12-24T18:49:01.747+0000] {logging_mixin.py:188} WARNING -   File "/usr/local/lib/python3.12/logging/__init__.py", line 999, in format
    return fmt.format(record)
           ^^^^^^^^^^^^^^^^^^
[2024-12-24T18:49:01.747+0000] {logging_mixin.py:188} WARNING -   File "/usr/local/lib/python3.12/logging/__init__.py", line 703, in format
    record.message = record.getMessage()
                     ^^^^^^^^^^^^^^^^^^^
[2024-12-24T18:49:01.748+0000] {logging_mixin.py:188} WARNING -   File "/usr/local/lib/python3.12/logging/__init__.py", line 392, in getMessage
    msg = msg % self.args
          ~~~~^~~~~~~~~~~
[2024-12-24T18:49:01.748+0000] {logging_mixin.py:188} WARNING - TypeError: not all arguments converted during string formatting
[2024-12-24T18:49:01.749+0000] {logging_mixin.py:188} WARNING - Call stack:
[2024-12-24T18:49:01.756+0000] {logging_mixin.py:188} WARNING -   File "/home/***/.local/bin/***", line 8, in <module>
    sys.exit(main())
[2024-12-24T18:49:01.756+0000] {logging_mixin.py:188} WARNING -   File "/home/***/.local/lib/python3.12/site-packages/***/__main__.py", line 58, in main
    args.func(args)
[2024-12-24T18:49:01.757+0000] {logging_mixin.py:188} WARNING -   File "/home/***/.local/lib/python3.12/site-packages/***/cli/cli_config.py", line 49, in command
    return func(*args, **kwargs)
[2024-12-24T18:49:01.758+0000] {logging_mixin.py:188} WARNING -   File "/home/***/.local/lib/python3.12/site-packages/***/utils/cli.py", line 114, in wrapper
    return f(*args, **kwargs)
[2024-12-24T18:49:01.758+0000] {logging_mixin.py:188} WARNING -   File "/home/***/.local/lib/python3.12/site-packages/***/utils/providers_configuration_loader.py", line 55, in wrapped_function
    return func(*args, **kwargs)
[2024-12-24T18:49:01.759+0000] {logging_mixin.py:188} WARNING -   File "/home/***/.local/lib/python3.12/site-packages/***/cli/commands/scheduler_command.py", line 58, in scheduler
    run_command_with_daemon_option(
[2024-12-24T18:49:01.759+0000] {logging_mixin.py:188} WARNING -   File "/home/***/.local/lib/python3.12/site-packages/***/cli/commands/daemon_utils.py", line 85, in run_command_with_daemon_option
    callback()
[2024-12-24T18:49:01.760+0000] {logging_mixin.py:188} WARNING -   File "/home/***/.local/lib/python3.12/site-packages/***/cli/commands/scheduler_command.py", line 61, in <lambda>
    callback=lambda: _run_scheduler_job(args),
[2024-12-24T18:49:01.760+0000] {logging_mixin.py:188} WARNING -   File "/home/***/.local/lib/python3.12/site-packages/***/cli/commands/scheduler_command.py", line 49, in _run_scheduler_job
    run_job(job=job_runner.job, execute_callable=job_runner._execute)
[2024-12-24T18:49:01.761+0000] {logging_mixin.py:188} WARNING -   File "/home/***/.local/lib/python3.12/site-packages/***/utils/session.py", line 79, in wrapper
    return func(*args, session=session, **kwargs)
[2024-12-24T18:49:01.762+0000] {logging_mixin.py:188} WARNING -   File "/home/***/.local/lib/python3.12/site-packages/***/jobs/job.py", line 402, in run_job
    return execute_job(job, execute_callable=execute_callable)
[2024-12-24T18:49:01.762+0000] {logging_mixin.py:188} WARNING -   File "/home/***/.local/lib/python3.12/site-packages/***/jobs/job.py", line 431, in execute_job
    ret = execute_callable()
[2024-12-24T18:49:01.763+0000] {logging_mixin.py:188} WARNING -   File "/home/***/.local/lib/python3.12/site-packages/***/jobs/scheduler_job_runner.py", line 834, in _execute
    self.job.executor.start()
[2024-12-24T18:49:01.764+0000] {logging_mixin.py:188} WARNING -   File "/home/***/.local/lib/python3.12/site-packages/***/executors/local_executor.py", line 373, in start
    self.impl.start()
[2024-12-24T18:49:01.764+0000] {logging_mixin.py:188} WARNING -   File "/home/***/.local/lib/python3.12/site-packages/***/executors/local_executor.py", line 312, in start
    worker.start()
[2024-12-24T18:49:01.765+0000] {logging_mixin.py:188} WARNING -   File "/usr/local/lib/python3.12/multiprocessing/process.py", line 121, in start
    self._popen = self._Popen(self)
[2024-12-24T18:49:01.766+0000] {logging_mixin.py:188} WARNING -   File "/usr/local/lib/python3.12/multiprocessing/context.py", line 224, in _Popen
    return _default_context.get_context().Process._Popen(process_obj)
[2024-12-24T18:49:01.766+0000] {logging_mixin.py:188} WARNING -   File "/usr/local/lib/python3.12/multiprocessing/context.py", line 282, in _Popen
    return Popen(process_obj)
[2024-12-24T18:49:01.767+0000] {logging_mixin.py:188} WARNING -   File "/usr/local/lib/python3.12/multiprocessing/popen_fork.py", line 19, in __init__
    self._launch(process_obj)
[2024-12-24T18:49:01.767+0000] {logging_mixin.py:188} WARNING -   File "/usr/local/lib/python3.12/multiprocessing/popen_fork.py", line 71, in _launch
    code = process_obj._bootstrap(parent_sentinel=child_r)
[2024-12-24T18:49:01.768+0000] {logging_mixin.py:188} WARNING -   File "/usr/local/lib/python3.12/multiprocessing/process.py", line 314, in _bootstrap
    self.run()
[2024-12-24T18:49:01.769+0000] {logging_mixin.py:188} WARNING -   File "/home/***/.local/lib/python3.12/site-packages/***/executors/local_executor.py", line 78, in run
    return super().run()
[2024-12-24T18:49:01.769+0000] {logging_mixin.py:188} WARNING -   File "/usr/local/lib/python3.12/multiprocessing/process.py", line 108, in run
    self._target(*self._args, **self._kwargs)
[2024-12-24T18:49:01.770+0000] {logging_mixin.py:188} WARNING -   File "/home/***/.local/lib/python3.12/site-packages/***/executors/local_executor.py", line 202, in do_work
    self.execute_work(key=key, command=command)
[2024-12-24T18:49:01.770+0000] {logging_mixin.py:188} WARNING -   File "/home/***/.local/lib/python3.12/site-packages/***/executors/local_executor.py", line 95, in execute_work
    state = self._execute_work_in_fork(command)
[2024-12-24T18:49:01.771+0000] {logging_mixin.py:188} WARNING -   File "/home/***/.local/lib/python3.12/site-packages/***/executors/local_executor.py", line 135, in _execute_work_in_fork
    args.func(args)
[2024-12-24T18:49:01.772+0000] {logging_mixin.py:188} WARNING -   File "/home/***/.local/lib/python3.12/site-packages/***/cli/cli_config.py", line 49, in command
    return func(*args, **kwargs)
[2024-12-24T18:49:01.772+0000] {logging_mixin.py:188} WARNING -   File "/home/***/.local/lib/python3.12/site-packages/***/utils/cli.py", line 114, in wrapper
    return f(*args, **kwargs)
[2024-12-24T18:49:01.773+0000] {logging_mixin.py:188} WARNING -   File "/home/***/.local/lib/python3.12/site-packages/***/cli/commands/task_command.py", line 441, in task_run
    task_return_code = _run_task_by_selected_method(args, _dag, ti)
[2024-12-24T18:49:01.774+0000] {logging_mixin.py:188} WARNING -   File "/home/***/.local/lib/python3.12/site-packages/***/cli/commands/task_command.py", line 219, in _run_task_by_selected_method
    return _run_task_by_local_task_job(args, ti)
[2024-12-24T18:49:01.774+0000] {logging_mixin.py:188} WARNING -   File "/home/***/.local/lib/python3.12/site-packages/***/cli/commands/task_command.py", line 281, in _run_task_by_local_task_job
    ret = run_job(job=job_runner.job, execute_callable=job_runner._execute)
[2024-12-24T18:49:01.775+0000] {logging_mixin.py:188} WARNING -   File "/home/***/.local/lib/python3.12/site-packages/***/utils/session.py", line 79, in wrapper
    return func(*args, session=session, **kwargs)
[2024-12-24T18:49:01.775+0000] {logging_mixin.py:188} WARNING -   File "/home/***/.local/lib/python3.12/site-packages/***/jobs/job.py", line 402, in run_job
    return execute_job(job, execute_callable=execute_callable)
[2024-12-24T18:49:01.776+0000] {logging_mixin.py:188} WARNING -   File "/home/***/.local/lib/python3.12/site-packages/***/jobs/job.py", line 431, in execute_job
    ret = execute_callable()
[2024-12-24T18:49:01.776+0000] {logging_mixin.py:188} WARNING -   File "/home/***/.local/lib/python3.12/site-packages/***/jobs/local_task_job_runner.py", line 168, in _execute
    self.task_runner.start()
[2024-12-24T18:49:01.777+0000] {logging_mixin.py:188} WARNING -   File "/home/***/.local/lib/python3.12/site-packages/***/task/task_runner/standard_task_runner.py", line 51, in start
    self.process = self._start_by_fork()
[2024-12-24T18:49:01.778+0000] {logging_mixin.py:188} WARNING -   File "/home/***/.local/lib/python3.12/site-packages/***/task/task_runner/standard_task_runner.py", line 103, in _start_by_fork
    ret = args.func(args, dag=self.dag)
[2024-12-24T18:49:01.778+0000] {logging_mixin.py:188} WARNING -   File "/home/***/.local/lib/python3.12/site-packages/***/cli/cli_config.py", line 49, in command
    return func(*args, **kwargs)
[2024-12-24T18:49:01.779+0000] {logging_mixin.py:188} WARNING -   File "/home/***/.local/lib/python3.12/site-packages/***/utils/cli.py", line 114, in wrapper
    return f(*args, **kwargs)
[2024-12-24T18:49:01.779+0000] {logging_mixin.py:188} WARNING -   File "/home/***/.local/lib/python3.12/site-packages/***/cli/commands/task_command.py", line 441, in task_run
    task_return_code = _run_task_by_selected_method(args, _dag, ti)
[2024-12-24T18:49:01.780+0000] {logging_mixin.py:188} WARNING -   File "/home/***/.local/lib/python3.12/site-packages/***/cli/commands/task_command.py", line 221, in _run_task_by_selected_method
    return _run_raw_task(args, ti)
[2024-12-24T18:49:01.781+0000] {logging_mixin.py:188} WARNING -   File "/home/***/.local/lib/python3.12/site-packages/***/cli/commands/task_command.py", line 300, in _run_raw_task
    return ti._run_raw_task(
[2024-12-24T18:49:01.781+0000] {logging_mixin.py:188} WARNING -   File "/home/***/.local/lib/python3.12/site-packages/***/utils/session.py", line 79, in wrapper
    return func(*args, session=session, **kwargs)
[2024-12-24T18:49:01.782+0000] {logging_mixin.py:188} WARNING -   File "/home/***/.local/lib/python3.12/site-packages/***/models/taskinstance.py", line 2479, in _run_raw_task
    self._execute_task_with_callbacks(context, test_mode, session=session)
[2024-12-24T18:49:01.782+0000] {logging_mixin.py:188} WARNING -   File "/home/***/.local/lib/python3.12/site-packages/***/models/taskinstance.py", line 2676, in _execute_task_with_callbacks
    result = self._execute_task(context, task_orig)
[2024-12-24T18:49:01.783+0000] {logging_mixin.py:188} WARNING -   File "/home/***/.local/lib/python3.12/site-packages/***/models/taskinstance.py", line 2701, in _execute_task
    return _execute_task(self, context, task_orig)
[2024-12-24T18:49:01.783+0000] {logging_mixin.py:188} WARNING -   File "/home/***/.local/lib/python3.12/site-packages/***/models/taskinstance.py", line 465, in _execute_task
    result = _execute_callable(context=context, **execute_callable_kwargs)
[2024-12-24T18:49:01.784+0000] {logging_mixin.py:188} WARNING -   File "/home/***/.local/lib/python3.12/site-packages/***/models/taskinstance.py", line 432, in _execute_callable
    return execute_callable(context=context, **execute_callable_kwargs)
[2024-12-24T18:49:01.785+0000] {logging_mixin.py:188} WARNING -   File "/home/***/.local/lib/python3.12/site-packages/***/models/baseoperator.py", line 401, in wrapper
    return func(self, *args, **kwargs)
[2024-12-24T18:49:01.786+0000] {logging_mixin.py:188} WARNING -   File "/home/***/.local/lib/python3.12/site-packages/***/operators/python.py", line 235, in execute
    return_value = self.execute_callable()
[2024-12-24T18:49:01.787+0000] {logging_mixin.py:188} WARNING -   File "/home/***/.local/lib/python3.12/site-packages/***/operators/python.py", line 252, in execute_callable
    return self.python_callable(*self.op_args, **self.op_kwargs)
[2024-12-24T18:49:01.787+0000] {logging_mixin.py:188} WARNING -   File "/opt/***/dags/pipeline_batch_visualize.py", line 86, in start_pipeline
    logging.info("Start pipeline:", DATE)
[2024-12-24T18:49:01.788+0000] {logging_mixin.py:188} WARNING -   File "/usr/local/lib/python3.12/logging/__init__.py", line 2216, in info
    root.info(msg, *args, **kwargs)
[2024-12-24T18:49:01.788+0000] {logging_mixin.py:188} WARNING -   File "/usr/local/lib/python3.12/logging/__init__.py", line 1539, in info
    self._log(INFO, msg, args, **kwargs)
[2024-12-24T18:49:01.789+0000] {logging_mixin.py:188} WARNING -   File "/usr/local/lib/python3.12/logging/__init__.py", line 1684, in _log
    self.handle(record)
[2024-12-24T18:49:01.789+0000] {logging_mixin.py:188} WARNING -   File "/usr/local/lib/python3.12/logging/__init__.py", line 1700, in handle
    self.callHandlers(record)
[2024-12-24T18:49:01.790+0000] {logging_mixin.py:188} WARNING -   File "/usr/local/lib/python3.12/logging/__init__.py", line 1762, in callHandlers
    hdlr.handle(record)
[2024-12-24T18:49:01.790+0000] {logging_mixin.py:188} WARNING -   File "/usr/local/lib/python3.12/logging/__init__.py", line 1028, in handle
    self.emit(record)
[2024-12-24T18:49:01.790+0000] {logging_mixin.py:188} WARNING -   File "/home/***/.local/lib/python3.12/site-packages/***/utils/log/file_task_handler.py", line 248, in emit
    self.handler.emit(record)
[2024-12-24T18:49:01.791+0000] {logging_mixin.py:188} WARNING - Message: 'Start pipeline:'
Arguments: ('2024-01-02',)
[2024-12-24T18:49:01.791+0000] {logging_mixin.py:188} WARNING - --- Logging error ---
[2024-12-24T18:49:01.792+0000] {logging_mixin.py:188} WARNING - Traceback (most recent call last):
[2024-12-24T18:49:01.792+0000] {logging_mixin.py:188} WARNING -   File "/usr/local/lib/python3.12/logging/__init__.py", line 1160, in emit
    msg = self.format(record)
          ^^^^^^^^^^^^^^^^^^^
[2024-12-24T18:49:01.793+0000] {logging_mixin.py:188} WARNING -   File "/usr/local/lib/python3.12/logging/__init__.py", line 999, in format
    return fmt.format(record)
           ^^^^^^^^^^^^^^^^^^
[2024-12-24T18:49:01.793+0000] {logging_mixin.py:188} WARNING -   File "/usr/local/lib/python3.12/logging/__init__.py", line 703, in format
    record.message = record.getMessage()
                     ^^^^^^^^^^^^^^^^^^^
[2024-12-24T18:49:01.794+0000] {logging_mixin.py:188} WARNING -   File "/usr/local/lib/python3.12/logging/__init__.py", line 392, in getMessage
    msg = msg % self.args
          ~~~~^~~~~~~~~~~
[2024-12-24T18:49:01.794+0000] {logging_mixin.py:188} WARNING - TypeError: not all arguments converted during string formatting
[2024-12-24T18:49:01.794+0000] {logging_mixin.py:188} WARNING - Call stack:
[2024-12-24T18:49:01.797+0000] {logging_mixin.py:188} WARNING -   File "/home/***/.local/bin/***", line 8, in <module>
    sys.exit(main())
[2024-12-24T18:49:01.798+0000] {logging_mixin.py:188} WARNING -   File "/home/***/.local/lib/python3.12/site-packages/***/__main__.py", line 58, in main
    args.func(args)
[2024-12-24T18:49:01.798+0000] {logging_mixin.py:188} WARNING -   File "/home/***/.local/lib/python3.12/site-packages/***/cli/cli_config.py", line 49, in command
    return func(*args, **kwargs)
[2024-12-24T18:49:01.799+0000] {logging_mixin.py:188} WARNING -   File "/home/***/.local/lib/python3.12/site-packages/***/utils/cli.py", line 114, in wrapper
    return f(*args, **kwargs)
[2024-12-24T18:49:01.799+0000] {logging_mixin.py:188} WARNING -   File "/home/***/.local/lib/python3.12/site-packages/***/utils/providers_configuration_loader.py", line 55, in wrapped_function
    return func(*args, **kwargs)
[2024-12-24T18:49:01.800+0000] {logging_mixin.py:188} WARNING -   File "/home/***/.local/lib/python3.12/site-packages/***/cli/commands/scheduler_command.py", line 58, in scheduler
    run_command_with_daemon_option(
[2024-12-24T18:49:01.800+0000] {logging_mixin.py:188} WARNING -   File "/home/***/.local/lib/python3.12/site-packages/***/cli/commands/daemon_utils.py", line 85, in run_command_with_daemon_option
    callback()
[2024-12-24T18:49:01.801+0000] {logging_mixin.py:188} WARNING -   File "/home/***/.local/lib/python3.12/site-packages/***/cli/commands/scheduler_command.py", line 61, in <lambda>
    callback=lambda: _run_scheduler_job(args),
[2024-12-24T18:49:01.802+0000] {logging_mixin.py:188} WARNING -   File "/home/***/.local/lib/python3.12/site-packages/***/cli/commands/scheduler_command.py", line 49, in _run_scheduler_job
    run_job(job=job_runner.job, execute_callable=job_runner._execute)
[2024-12-24T18:49:01.803+0000] {logging_mixin.py:188} WARNING -   File "/home/***/.local/lib/python3.12/site-packages/***/utils/session.py", line 79, in wrapper
    return func(*args, session=session, **kwargs)
[2024-12-24T18:49:01.804+0000] {logging_mixin.py:188} WARNING -   File "/home/***/.local/lib/python3.12/site-packages/***/jobs/job.py", line 402, in run_job
    return execute_job(job, execute_callable=execute_callable)
[2024-12-24T18:49:01.804+0000] {logging_mixin.py:188} WARNING -   File "/home/***/.local/lib/python3.12/site-packages/***/jobs/job.py", line 431, in execute_job
    ret = execute_callable()
[2024-12-24T18:49:01.805+0000] {logging_mixin.py:188} WARNING -   File "/home/***/.local/lib/python3.12/site-packages/***/jobs/scheduler_job_runner.py", line 834, in _execute
    self.job.executor.start()
[2024-12-24T18:49:01.805+0000] {logging_mixin.py:188} WARNING -   File "/home/***/.local/lib/python3.12/site-packages/***/executors/local_executor.py", line 373, in start
    self.impl.start()
[2024-12-24T18:49:01.806+0000] {logging_mixin.py:188} WARNING -   File "/home/***/.local/lib/python3.12/site-packages/***/executors/local_executor.py", line 312, in start
    worker.start()
[2024-12-24T18:49:01.807+0000] {logging_mixin.py:188} WARNING -   File "/usr/local/lib/python3.12/multiprocessing/process.py", line 121, in start
    self._popen = self._Popen(self)
[2024-12-24T18:49:01.808+0000] {logging_mixin.py:188} WARNING -   File "/usr/local/lib/python3.12/multiprocessing/context.py", line 224, in _Popen
    return _default_context.get_context().Process._Popen(process_obj)
[2024-12-24T18:49:01.808+0000] {logging_mixin.py:188} WARNING -   File "/usr/local/lib/python3.12/multiprocessing/context.py", line 282, in _Popen
    return Popen(process_obj)
[2024-12-24T18:49:01.809+0000] {logging_mixin.py:188} WARNING -   File "/usr/local/lib/python3.12/multiprocessing/popen_fork.py", line 19, in __init__
    self._launch(process_obj)
[2024-12-24T18:49:01.809+0000] {logging_mixin.py:188} WARNING -   File "/usr/local/lib/python3.12/multiprocessing/popen_fork.py", line 71, in _launch
    code = process_obj._bootstrap(parent_sentinel=child_r)
[2024-12-24T18:49:01.810+0000] {logging_mixin.py:188} WARNING -   File "/usr/local/lib/python3.12/multiprocessing/process.py", line 314, in _bootstrap
    self.run()
[2024-12-24T18:49:01.810+0000] {logging_mixin.py:188} WARNING -   File "/home/***/.local/lib/python3.12/site-packages/***/executors/local_executor.py", line 78, in run
    return super().run()
[2024-12-24T18:49:01.811+0000] {logging_mixin.py:188} WARNING -   File "/usr/local/lib/python3.12/multiprocessing/process.py", line 108, in run
    self._target(*self._args, **self._kwargs)
[2024-12-24T18:49:01.811+0000] {logging_mixin.py:188} WARNING -   File "/home/***/.local/lib/python3.12/site-packages/***/executors/local_executor.py", line 202, in do_work
    self.execute_work(key=key, command=command)
[2024-12-24T18:49:01.812+0000] {logging_mixin.py:188} WARNING -   File "/home/***/.local/lib/python3.12/site-packages/***/executors/local_executor.py", line 95, in execute_work
    state = self._execute_work_in_fork(command)
[2024-12-24T18:49:01.813+0000] {logging_mixin.py:188} WARNING -   File "/home/***/.local/lib/python3.12/site-packages/***/executors/local_executor.py", line 135, in _execute_work_in_fork
    args.func(args)
[2024-12-24T18:49:01.814+0000] {logging_mixin.py:188} WARNING -   File "/home/***/.local/lib/python3.12/site-packages/***/cli/cli_config.py", line 49, in command
    return func(*args, **kwargs)
[2024-12-24T18:49:01.814+0000] {logging_mixin.py:188} WARNING -   File "/home/***/.local/lib/python3.12/site-packages/***/utils/cli.py", line 114, in wrapper
    return f(*args, **kwargs)
[2024-12-24T18:49:01.815+0000] {logging_mixin.py:188} WARNING -   File "/home/***/.local/lib/python3.12/site-packages/***/cli/commands/task_command.py", line 441, in task_run
    task_return_code = _run_task_by_selected_method(args, _dag, ti)
[2024-12-24T18:49:01.816+0000] {logging_mixin.py:188} WARNING -   File "/home/***/.local/lib/python3.12/site-packages/***/cli/commands/task_command.py", line 219, in _run_task_by_selected_method
    return _run_task_by_local_task_job(args, ti)
[2024-12-24T18:49:01.817+0000] {logging_mixin.py:188} WARNING -   File "/home/***/.local/lib/python3.12/site-packages/***/cli/commands/task_command.py", line 281, in _run_task_by_local_task_job
    ret = run_job(job=job_runner.job, execute_callable=job_runner._execute)
[2024-12-24T18:49:01.819+0000] {logging_mixin.py:188} WARNING -   File "/home/***/.local/lib/python3.12/site-packages/***/utils/session.py", line 79, in wrapper
    return func(*args, session=session, **kwargs)
[2024-12-24T18:49:01.819+0000] {logging_mixin.py:188} WARNING -   File "/home/***/.local/lib/python3.12/site-packages/***/jobs/job.py", line 402, in run_job
    return execute_job(job, execute_callable=execute_callable)
[2024-12-24T18:49:01.820+0000] {logging_mixin.py:188} WARNING -   File "/home/***/.local/lib/python3.12/site-packages/***/jobs/job.py", line 431, in execute_job
    ret = execute_callable()
[2024-12-24T18:49:01.821+0000] {logging_mixin.py:188} WARNING -   File "/home/***/.local/lib/python3.12/site-packages/***/jobs/local_task_job_runner.py", line 168, in _execute
    self.task_runner.start()
[2024-12-24T18:49:01.821+0000] {logging_mixin.py:188} WARNING -   File "/home/***/.local/lib/python3.12/site-packages/***/task/task_runner/standard_task_runner.py", line 51, in start
    self.process = self._start_by_fork()
[2024-12-24T18:49:01.822+0000] {logging_mixin.py:188} WARNING -   File "/home/***/.local/lib/python3.12/site-packages/***/task/task_runner/standard_task_runner.py", line 103, in _start_by_fork
    ret = args.func(args, dag=self.dag)
[2024-12-24T18:49:01.823+0000] {logging_mixin.py:188} WARNING -   File "/home/***/.local/lib/python3.12/site-packages/***/cli/cli_config.py", line 49, in command
    return func(*args, **kwargs)
[2024-12-24T18:49:01.824+0000] {logging_mixin.py:188} WARNING -   File "/home/***/.local/lib/python3.12/site-packages/***/utils/cli.py", line 114, in wrapper
    return f(*args, **kwargs)
[2024-12-24T18:49:01.825+0000] {logging_mixin.py:188} WARNING -   File "/home/***/.local/lib/python3.12/site-packages/***/cli/commands/task_command.py", line 441, in task_run
    task_return_code = _run_task_by_selected_method(args, _dag, ti)
[2024-12-24T18:49:01.826+0000] {logging_mixin.py:188} WARNING -   File "/home/***/.local/lib/python3.12/site-packages/***/cli/commands/task_command.py", line 221, in _run_task_by_selected_method
    return _run_raw_task(args, ti)
[2024-12-24T18:49:01.826+0000] {logging_mixin.py:188} WARNING -   File "/home/***/.local/lib/python3.12/site-packages/***/cli/commands/task_command.py", line 300, in _run_raw_task
    return ti._run_raw_task(
[2024-12-24T18:49:01.827+0000] {logging_mixin.py:188} WARNING -   File "/home/***/.local/lib/python3.12/site-packages/***/utils/session.py", line 79, in wrapper
    return func(*args, session=session, **kwargs)
[2024-12-24T18:49:01.828+0000] {logging_mixin.py:188} WARNING -   File "/home/***/.local/lib/python3.12/site-packages/***/models/taskinstance.py", line 2479, in _run_raw_task
    self._execute_task_with_callbacks(context, test_mode, session=session)
[2024-12-24T18:49:01.829+0000] {logging_mixin.py:188} WARNING -   File "/home/***/.local/lib/python3.12/site-packages/***/models/taskinstance.py", line 2676, in _execute_task_with_callbacks
    result = self._execute_task(context, task_orig)
[2024-12-24T18:49:01.829+0000] {logging_mixin.py:188} WARNING -   File "/home/***/.local/lib/python3.12/site-packages/***/models/taskinstance.py", line 2701, in _execute_task
    return _execute_task(self, context, task_orig)
[2024-12-24T18:49:01.830+0000] {logging_mixin.py:188} WARNING -   File "/home/***/.local/lib/python3.12/site-packages/***/models/taskinstance.py", line 465, in _execute_task
    result = _execute_callable(context=context, **execute_callable_kwargs)
[2024-12-24T18:49:01.831+0000] {logging_mixin.py:188} WARNING -   File "/home/***/.local/lib/python3.12/site-packages/***/models/taskinstance.py", line 432, in _execute_callable
    return execute_callable(context=context, **execute_callable_kwargs)
[2024-12-24T18:49:01.831+0000] {logging_mixin.py:188} WARNING -   File "/home/***/.local/lib/python3.12/site-packages/***/models/baseoperator.py", line 401, in wrapper
    return func(self, *args, **kwargs)
[2024-12-24T18:49:01.832+0000] {logging_mixin.py:188} WARNING -   File "/home/***/.local/lib/python3.12/site-packages/***/operators/python.py", line 235, in execute
    return_value = self.execute_callable()
[2024-12-24T18:49:01.833+0000] {logging_mixin.py:188} WARNING -   File "/home/***/.local/lib/python3.12/site-packages/***/operators/python.py", line 252, in execute_callable
    return self.python_callable(*self.op_args, **self.op_kwargs)
[2024-12-24T18:49:01.833+0000] {logging_mixin.py:188} WARNING -   File "/opt/***/dags/pipeline_batch_visualize.py", line 87, in start_pipeline
    logging.info("Args raw to processed:", args_raw_to_processed)
[2024-12-24T18:49:01.834+0000] {logging_mixin.py:188} WARNING -   File "/usr/local/lib/python3.12/logging/__init__.py", line 2216, in info
    root.info(msg, *args, **kwargs)
[2024-12-24T18:49:01.835+0000] {logging_mixin.py:188} WARNING -   File "/usr/local/lib/python3.12/logging/__init__.py", line 1539, in info
    self._log(INFO, msg, args, **kwargs)
[2024-12-24T18:49:01.836+0000] {logging_mixin.py:188} WARNING -   File "/usr/local/lib/python3.12/logging/__init__.py", line 1684, in _log
    self.handle(record)
[2024-12-24T18:49:01.837+0000] {logging_mixin.py:188} WARNING -   File "/usr/local/lib/python3.12/logging/__init__.py", line 1700, in handle
    self.callHandlers(record)
[2024-12-24T18:49:01.837+0000] {logging_mixin.py:188} WARNING -   File "/usr/local/lib/python3.12/logging/__init__.py", line 1762, in callHandlers
    hdlr.handle(record)
[2024-12-24T18:49:01.838+0000] {logging_mixin.py:188} WARNING -   File "/usr/local/lib/python3.12/logging/__init__.py", line 1028, in handle
    self.emit(record)
[2024-12-24T18:49:01.839+0000] {logging_mixin.py:188} WARNING -   File "/home/***/.local/lib/python3.12/site-packages/***/utils/log/file_task_handler.py", line 248, in emit
    self.handler.emit(record)
[2024-12-24T18:49:01.839+0000] {logging_mixin.py:188} WARNING - Message: 'Args raw to processed:'
Arguments: (Config(minio_access_key='Xs27nx9M4HgPQ5PXZiUE', minio_secret_key='8iifKZlUZh1NRbepsISUMdg1CxlaIC6OSPQk5X59', endpoint_url='192.168.1.12:9000', jars_dir='/opt/***/jars', taxi_lookup_path='s3a://raw/taxi_lookup.csv', num_output_files=1, green_path_src='s3a://raw/cdc_db/2024/01/02/data', yellow_path_src='s3a://raw/yellow/2024/01/02.parquet', green_path_dist='s3a://processed/data/green/2024/01/02', yellow_path_dist='s3a://processed/data/yellow/2024/01/02'),)
[2024-12-24T18:49:01.840+0000] {logging_mixin.py:188} WARNING - --- Logging error ---
[2024-12-24T18:49:01.841+0000] {logging_mixin.py:188} WARNING - Traceback (most recent call last):
[2024-12-24T18:49:01.842+0000] {logging_mixin.py:188} WARNING -   File "/usr/local/lib/python3.12/logging/__init__.py", line 1160, in emit
    msg = self.format(record)
          ^^^^^^^^^^^^^^^^^^^
[2024-12-24T18:49:01.842+0000] {logging_mixin.py:188} WARNING -   File "/usr/local/lib/python3.12/logging/__init__.py", line 999, in format
    return fmt.format(record)
           ^^^^^^^^^^^^^^^^^^
[2024-12-24T18:49:01.843+0000] {logging_mixin.py:188} WARNING -   File "/usr/local/lib/python3.12/logging/__init__.py", line 703, in format
    record.message = record.getMessage()
                     ^^^^^^^^^^^^^^^^^^^
[2024-12-24T18:49:01.844+0000] {logging_mixin.py:188} WARNING -   File "/usr/local/lib/python3.12/logging/__init__.py", line 392, in getMessage
    msg = msg % self.args
          ~~~~^~~~~~~~~~~
[2024-12-24T18:49:01.844+0000] {logging_mixin.py:188} WARNING - TypeError: not all arguments converted during string formatting
[2024-12-24T18:49:01.845+0000] {logging_mixin.py:188} WARNING - Call stack:
[2024-12-24T18:49:01.847+0000] {logging_mixin.py:188} WARNING -   File "/home/***/.local/bin/***", line 8, in <module>
    sys.exit(main())
[2024-12-24T18:49:01.848+0000] {logging_mixin.py:188} WARNING -   File "/home/***/.local/lib/python3.12/site-packages/***/__main__.py", line 58, in main
    args.func(args)
[2024-12-24T18:49:01.849+0000] {logging_mixin.py:188} WARNING -   File "/home/***/.local/lib/python3.12/site-packages/***/cli/cli_config.py", line 49, in command
    return func(*args, **kwargs)
[2024-12-24T18:49:01.850+0000] {logging_mixin.py:188} WARNING -   File "/home/***/.local/lib/python3.12/site-packages/***/utils/cli.py", line 114, in wrapper
    return f(*args, **kwargs)
[2024-12-24T18:49:01.850+0000] {logging_mixin.py:188} WARNING -   File "/home/***/.local/lib/python3.12/site-packages/***/utils/providers_configuration_loader.py", line 55, in wrapped_function
    return func(*args, **kwargs)
[2024-12-24T18:49:01.851+0000] {logging_mixin.py:188} WARNING -   File "/home/***/.local/lib/python3.12/site-packages/***/cli/commands/scheduler_command.py", line 58, in scheduler
    run_command_with_daemon_option(
[2024-12-24T18:49:01.852+0000] {logging_mixin.py:188} WARNING -   File "/home/***/.local/lib/python3.12/site-packages/***/cli/commands/daemon_utils.py", line 85, in run_command_with_daemon_option
    callback()
[2024-12-24T18:49:01.853+0000] {logging_mixin.py:188} WARNING -   File "/home/***/.local/lib/python3.12/site-packages/***/cli/commands/scheduler_command.py", line 61, in <lambda>
    callback=lambda: _run_scheduler_job(args),
[2024-12-24T18:49:01.853+0000] {logging_mixin.py:188} WARNING -   File "/home/***/.local/lib/python3.12/site-packages/***/cli/commands/scheduler_command.py", line 49, in _run_scheduler_job
    run_job(job=job_runner.job, execute_callable=job_runner._execute)
[2024-12-24T18:49:01.854+0000] {logging_mixin.py:188} WARNING -   File "/home/***/.local/lib/python3.12/site-packages/***/utils/session.py", line 79, in wrapper
    return func(*args, session=session, **kwargs)
[2024-12-24T18:49:01.855+0000] {logging_mixin.py:188} WARNING -   File "/home/***/.local/lib/python3.12/site-packages/***/jobs/job.py", line 402, in run_job
    return execute_job(job, execute_callable=execute_callable)
[2024-12-24T18:49:01.856+0000] {logging_mixin.py:188} WARNING -   File "/home/***/.local/lib/python3.12/site-packages/***/jobs/job.py", line 431, in execute_job
    ret = execute_callable()
[2024-12-24T18:49:01.857+0000] {logging_mixin.py:188} WARNING -   File "/home/***/.local/lib/python3.12/site-packages/***/jobs/scheduler_job_runner.py", line 834, in _execute
    self.job.executor.start()
[2024-12-24T18:49:01.857+0000] {logging_mixin.py:188} WARNING -   File "/home/***/.local/lib/python3.12/site-packages/***/executors/local_executor.py", line 373, in start
    self.impl.start()
[2024-12-24T18:49:01.858+0000] {logging_mixin.py:188} WARNING -   File "/home/***/.local/lib/python3.12/site-packages/***/executors/local_executor.py", line 312, in start
    worker.start()
[2024-12-24T18:49:01.859+0000] {logging_mixin.py:188} WARNING -   File "/usr/local/lib/python3.12/multiprocessing/process.py", line 121, in start
    self._popen = self._Popen(self)
[2024-12-24T18:49:01.859+0000] {logging_mixin.py:188} WARNING -   File "/usr/local/lib/python3.12/multiprocessing/context.py", line 224, in _Popen
    return _default_context.get_context().Process._Popen(process_obj)
[2024-12-24T18:49:01.860+0000] {logging_mixin.py:188} WARNING -   File "/usr/local/lib/python3.12/multiprocessing/context.py", line 282, in _Popen
    return Popen(process_obj)
[2024-12-24T18:49:01.860+0000] {logging_mixin.py:188} WARNING -   File "/usr/local/lib/python3.12/multiprocessing/popen_fork.py", line 19, in __init__
    self._launch(process_obj)
[2024-12-24T18:49:01.860+0000] {logging_mixin.py:188} WARNING -   File "/usr/local/lib/python3.12/multiprocessing/popen_fork.py", line 71, in _launch
    code = process_obj._bootstrap(parent_sentinel=child_r)
[2024-12-24T18:49:01.861+0000] {logging_mixin.py:188} WARNING -   File "/usr/local/lib/python3.12/multiprocessing/process.py", line 314, in _bootstrap
    self.run()
[2024-12-24T18:49:01.861+0000] {logging_mixin.py:188} WARNING -   File "/home/***/.local/lib/python3.12/site-packages/***/executors/local_executor.py", line 78, in run
    return super().run()
[2024-12-24T18:49:01.862+0000] {logging_mixin.py:188} WARNING -   File "/usr/local/lib/python3.12/multiprocessing/process.py", line 108, in run
    self._target(*self._args, **self._kwargs)
[2024-12-24T18:49:01.863+0000] {logging_mixin.py:188} WARNING -   File "/home/***/.local/lib/python3.12/site-packages/***/executors/local_executor.py", line 202, in do_work
    self.execute_work(key=key, command=command)
[2024-12-24T18:49:01.864+0000] {logging_mixin.py:188} WARNING -   File "/home/***/.local/lib/python3.12/site-packages/***/executors/local_executor.py", line 95, in execute_work
    state = self._execute_work_in_fork(command)
[2024-12-24T18:49:01.864+0000] {logging_mixin.py:188} WARNING -   File "/home/***/.local/lib/python3.12/site-packages/***/executors/local_executor.py", line 135, in _execute_work_in_fork
    args.func(args)
[2024-12-24T18:49:01.865+0000] {logging_mixin.py:188} WARNING -   File "/home/***/.local/lib/python3.12/site-packages/***/cli/cli_config.py", line 49, in command
    return func(*args, **kwargs)
[2024-12-24T18:49:01.866+0000] {logging_mixin.py:188} WARNING -   File "/home/***/.local/lib/python3.12/site-packages/***/utils/cli.py", line 114, in wrapper
    return f(*args, **kwargs)
[2024-12-24T18:49:01.866+0000] {logging_mixin.py:188} WARNING -   File "/home/***/.local/lib/python3.12/site-packages/***/cli/commands/task_command.py", line 441, in task_run
    task_return_code = _run_task_by_selected_method(args, _dag, ti)
[2024-12-24T18:49:01.867+0000] {logging_mixin.py:188} WARNING -   File "/home/***/.local/lib/python3.12/site-packages/***/cli/commands/task_command.py", line 219, in _run_task_by_selected_method
    return _run_task_by_local_task_job(args, ti)
[2024-12-24T18:49:01.868+0000] {logging_mixin.py:188} WARNING -   File "/home/***/.local/lib/python3.12/site-packages/***/cli/commands/task_command.py", line 281, in _run_task_by_local_task_job
    ret = run_job(job=job_runner.job, execute_callable=job_runner._execute)
[2024-12-24T18:49:01.869+0000] {logging_mixin.py:188} WARNING -   File "/home/***/.local/lib/python3.12/site-packages/***/utils/session.py", line 79, in wrapper
    return func(*args, session=session, **kwargs)
[2024-12-24T18:49:01.870+0000] {logging_mixin.py:188} WARNING -   File "/home/***/.local/lib/python3.12/site-packages/***/jobs/job.py", line 402, in run_job
    return execute_job(job, execute_callable=execute_callable)
[2024-12-24T18:49:01.871+0000] {logging_mixin.py:188} WARNING -   File "/home/***/.local/lib/python3.12/site-packages/***/jobs/job.py", line 431, in execute_job
    ret = execute_callable()
[2024-12-24T18:49:01.871+0000] {logging_mixin.py:188} WARNING -   File "/home/***/.local/lib/python3.12/site-packages/***/jobs/local_task_job_runner.py", line 168, in _execute
    self.task_runner.start()
[2024-12-24T18:49:01.872+0000] {logging_mixin.py:188} WARNING -   File "/home/***/.local/lib/python3.12/site-packages/***/task/task_runner/standard_task_runner.py", line 51, in start
    self.process = self._start_by_fork()
[2024-12-24T18:49:01.872+0000] {logging_mixin.py:188} WARNING -   File "/home/***/.local/lib/python3.12/site-packages/***/task/task_runner/standard_task_runner.py", line 103, in _start_by_fork
    ret = args.func(args, dag=self.dag)
[2024-12-24T18:49:01.873+0000] {logging_mixin.py:188} WARNING -   File "/home/***/.local/lib/python3.12/site-packages/***/cli/cli_config.py", line 49, in command
    return func(*args, **kwargs)
[2024-12-24T18:49:01.874+0000] {logging_mixin.py:188} WARNING -   File "/home/***/.local/lib/python3.12/site-packages/***/utils/cli.py", line 114, in wrapper
    return f(*args, **kwargs)
[2024-12-24T18:49:01.874+0000] {logging_mixin.py:188} WARNING -   File "/home/***/.local/lib/python3.12/site-packages/***/cli/commands/task_command.py", line 441, in task_run
    task_return_code = _run_task_by_selected_method(args, _dag, ti)
[2024-12-24T18:49:01.875+0000] {logging_mixin.py:188} WARNING -   File "/home/***/.local/lib/python3.12/site-packages/***/cli/commands/task_command.py", line 221, in _run_task_by_selected_method
    return _run_raw_task(args, ti)
[2024-12-24T18:49:01.876+0000] {logging_mixin.py:188} WARNING -   File "/home/***/.local/lib/python3.12/site-packages/***/cli/commands/task_command.py", line 300, in _run_raw_task
    return ti._run_raw_task(
[2024-12-24T18:49:01.877+0000] {logging_mixin.py:188} WARNING -   File "/home/***/.local/lib/python3.12/site-packages/***/utils/session.py", line 79, in wrapper
    return func(*args, session=session, **kwargs)
[2024-12-24T18:49:01.877+0000] {logging_mixin.py:188} WARNING -   File "/home/***/.local/lib/python3.12/site-packages/***/models/taskinstance.py", line 2479, in _run_raw_task
    self._execute_task_with_callbacks(context, test_mode, session=session)
[2024-12-24T18:49:01.878+0000] {logging_mixin.py:188} WARNING -   File "/home/***/.local/lib/python3.12/site-packages/***/models/taskinstance.py", line 2676, in _execute_task_with_callbacks
    result = self._execute_task(context, task_orig)
[2024-12-24T18:49:01.879+0000] {logging_mixin.py:188} WARNING -   File "/home/***/.local/lib/python3.12/site-packages/***/models/taskinstance.py", line 2701, in _execute_task
    return _execute_task(self, context, task_orig)
[2024-12-24T18:49:01.880+0000] {logging_mixin.py:188} WARNING -   File "/home/***/.local/lib/python3.12/site-packages/***/models/taskinstance.py", line 465, in _execute_task
    result = _execute_callable(context=context, **execute_callable_kwargs)
[2024-12-24T18:49:01.881+0000] {logging_mixin.py:188} WARNING -   File "/home/***/.local/lib/python3.12/site-packages/***/models/taskinstance.py", line 432, in _execute_callable
    return execute_callable(context=context, **execute_callable_kwargs)
[2024-12-24T18:49:01.882+0000] {logging_mixin.py:188} WARNING -   File "/home/***/.local/lib/python3.12/site-packages/***/models/baseoperator.py", line 401, in wrapper
    return func(self, *args, **kwargs)
[2024-12-24T18:49:01.883+0000] {logging_mixin.py:188} WARNING -   File "/home/***/.local/lib/python3.12/site-packages/***/operators/python.py", line 235, in execute
    return_value = self.execute_callable()
[2024-12-24T18:49:01.883+0000] {logging_mixin.py:188} WARNING -   File "/home/***/.local/lib/python3.12/site-packages/***/operators/python.py", line 252, in execute_callable
    return self.python_callable(*self.op_args, **self.op_kwargs)
[2024-12-24T18:49:01.884+0000] {logging_mixin.py:188} WARNING -   File "/opt/***/dags/pipeline_batch_visualize.py", line 88, in start_pipeline
    logging.info("Args spark to bigquery:", args_spark_to_bigquery)
[2024-12-24T18:49:01.885+0000] {logging_mixin.py:188} WARNING -   File "/usr/local/lib/python3.12/logging/__init__.py", line 2216, in info
    root.info(msg, *args, **kwargs)
[2024-12-24T18:49:01.886+0000] {logging_mixin.py:188} WARNING -   File "/usr/local/lib/python3.12/logging/__init__.py", line 1539, in info
    self._log(INFO, msg, args, **kwargs)
[2024-12-24T18:49:01.887+0000] {logging_mixin.py:188} WARNING -   File "/usr/local/lib/python3.12/logging/__init__.py", line 1684, in _log
    self.handle(record)
[2024-12-24T18:49:01.887+0000] {logging_mixin.py:188} WARNING -   File "/usr/local/lib/python3.12/logging/__init__.py", line 1700, in handle
    self.callHandlers(record)
[2024-12-24T18:49:01.888+0000] {logging_mixin.py:188} WARNING -   File "/usr/local/lib/python3.12/logging/__init__.py", line 1762, in callHandlers
    hdlr.handle(record)
[2024-12-24T18:49:01.889+0000] {logging_mixin.py:188} WARNING -   File "/usr/local/lib/python3.12/logging/__init__.py", line 1028, in handle
    self.emit(record)
[2024-12-24T18:49:01.889+0000] {logging_mixin.py:188} WARNING -   File "/home/***/.local/lib/python3.12/site-packages/***/utils/log/file_task_handler.py", line 248, in emit
    self.handler.emit(record)
[2024-12-24T18:49:01.890+0000] {logging_mixin.py:188} WARNING - Message: 'Args spark to bigquery:'
Arguments: (Config(max_memory='2g', minio_endpoint='192.168.1.12:9000', minio_access_key='Xs27nx9M4HgPQ5PXZiUE', minio_secret_key='8iifKZlUZh1NRbepsISUMdg1CxlaIC6OSPQk5X59', jars_dir='/opt/***/jars', bucket_name='processed', year='2024', month='01', day='02', date='2024-01-02', taxi_lookup_path='s3a://raw/taxi_lookup.csv', bq_project_id='bigdata-445102', bq_dataset_id='data_warehouse', path_auth_file='/opt/***/data/auth_gg_bigquery.json'),)
[2024-12-24T18:49:01.892+0000] {pipeline_batch_visualize.py:93} INFO - Path auth exist
[2024-12-24T18:49:01.892+0000] {pipeline_batch_visualize.py:94} INFO - /opt/***/data/auth_gg_bigquery.json
[2024-12-24T18:49:01.893+0000] {taskinstance.py:441} INFO - ::group::Post task execution logs
[2024-12-24T18:49:01.894+0000] {taskinstance.py:2905} ERROR - Task failed with exception
Traceback (most recent call last):
  File "/home/airflow/.local/lib/python3.12/site-packages/airflow/models/taskinstance.py", line 465, in _execute_task
    result = _execute_callable(context=context, **execute_callable_kwargs)
             ^^^^^^^^^^^^^^^^^^^^^^^^^^^^^^^^^^^^^^^^^^^^^^^^^^^^^^^^^^^^^
  File "/home/airflow/.local/lib/python3.12/site-packages/airflow/models/taskinstance.py", line 432, in _execute_callable
    return execute_callable(context=context, **execute_callable_kwargs)
           ^^^^^^^^^^^^^^^^^^^^^^^^^^^^^^^^^^^^^^^^^^^^^^^^^^^^^^^^^^^^
  File "/home/airflow/.local/lib/python3.12/site-packages/airflow/models/baseoperator.py", line 401, in wrapper
    return func(self, *args, **kwargs)
           ^^^^^^^^^^^^^^^^^^^^^^^^^^^
  File "/home/airflow/.local/lib/python3.12/site-packages/airflow/operators/python.py", line 235, in execute
    return_value = self.execute_callable()
                   ^^^^^^^^^^^^^^^^^^^^^^^
  File "/home/airflow/.local/lib/python3.12/site-packages/airflow/operators/python.py", line 252, in execute_callable
    return self.python_callable(*self.op_args, **self.op_kwargs)
           ^^^^^^^^^^^^^^^^^^^^^^^^^^^^^^^^^^^^^^^^^^^^^^^^^^^^^
  File "/opt/airflow/dags/pipeline_batch_visualize.py", line 95, in start_pipeline
    test_interact_with_windows()
  File "/opt/airflow/dags/pipeline_batch_visualize.py", line 80, in test_interact_with_windows
    with open(windows_path, "w") as f:
         ^^^^^^^^^^^^^^^^^^^^^^^
FileNotFoundError: [Errno 2] No such file or directory: '/mnt/host/e/test.txt'
[2024-12-24T18:49:01.905+0000] {taskinstance.py:1206} INFO - Marking task as FAILED. dag_id=pipeline_batch_visualize, task_id=start, run_id=manual__2024-12-24T18:48:59.634517+00:00, execution_date=20241224T184859, start_date=20241224T184901, end_date=20241224T184901
[2024-12-24T18:49:01.920+0000] {standard_task_runner.py:110} ERROR - Failed to execute job 340 for task start ([Errno 2] No such file or directory: '/mnt/host/e/test.txt'; 9000)
[2024-12-24T18:49:01.965+0000] {local_task_job_runner.py:240} INFO - Task exited with return code 1
[2024-12-24T18:49:01.990+0000] {taskinstance.py:3503} INFO - 0 downstream tasks scheduled from follow-on schedule check
[2024-12-24T18:49:01.998+0000] {local_task_job_runner.py:222} INFO - ::endgroup::
