[2024-12-23T09:09:09.165+0000] {local_task_job_runner.py:120} INFO - ::group::Pre task execution logs
[2024-12-23T09:09:09.202+0000] {taskinstance.py:2076} INFO - Dependencies all met for dep_context=non-requeueable deps ti=<TaskInstance: streaming_pipeline.image_to_datalake manual__2024-12-23T09:09:05.347904+00:00 [queued]>
[2024-12-23T09:09:09.211+0000] {taskinstance.py:2076} INFO - Dependencies all met for dep_context=requeueable deps ti=<TaskInstance: streaming_pipeline.image_to_datalake manual__2024-12-23T09:09:05.347904+00:00 [queued]>
[2024-12-23T09:09:09.212+0000] {taskinstance.py:2306} INFO - Starting attempt 1 of 1
[2024-12-23T09:09:09.234+0000] {taskinstance.py:2330} INFO - Executing <Task(PythonOperator): image_to_datalake> on 2024-12-23 09:09:05.347904+00:00
[2024-12-23T09:09:09.241+0000] {standard_task_runner.py:63} INFO - Started process 2376 to run task
[2024-12-23T09:09:09.243+0000] {standard_task_runner.py:90} INFO - Running: ['***', 'tasks', 'run', 'streaming_pipeline', 'image_to_datalake', 'manual__2024-12-23T09:09:05.347904+00:00', '--job-id', '73', '--raw', '--subdir', 'DAGS_FOLDER/pipline_stream.py', '--cfg-path', '/tmp/tmpgun5ubds']
[2024-12-23T09:09:09.245+0000] {standard_task_runner.py:91} INFO - Job 73: Subtask image_to_datalake
[2024-12-23T09:09:09.299+0000] {task_command.py:426} INFO - Running <TaskInstance: streaming_pipeline.image_to_datalake manual__2024-12-23T09:09:05.347904+00:00 [running]> on host 0b4a5bf62610
[2024-12-23T09:09:09.389+0000] {taskinstance.py:2648} INFO - Exporting env vars: AIRFLOW_CTX_DAG_OWNER='***' AIRFLOW_CTX_DAG_ID='streaming_pipeline' AIRFLOW_CTX_TASK_ID='image_to_datalake' AIRFLOW_CTX_EXECUTION_DATE='2024-12-23T09:09:05.347904+00:00' AIRFLOW_CTX_TRY_NUMBER='1' AIRFLOW_CTX_DAG_RUN_ID='manual__2024-12-23T09:09:05.347904+00:00'
[2024-12-23T09:09:09.391+0000] {taskinstance.py:430} INFO - ::endgroup::
[2024-12-23T09:09:09.406+0000] {connectionpool.py:874} WARNING - Retrying (Retry(total=4, connect=None, read=None, redirect=None, status=None)) after connection broken by 'NewConnectionError('<urllib3.connection.HTTPConnection object at 0x7f39ad5378c0>: Failed to establish a new connection: [Errno 111] Connection refused')': /raw?location=
[2024-12-23T09:09:09.808+0000] {connectionpool.py:874} WARNING - Retrying (Retry(total=3, connect=None, read=None, redirect=None, status=None)) after connection broken by 'NewConnectionError('<urllib3.connection.HTTPConnection object at 0x7f39932524b0>: Failed to establish a new connection: [Errno 111] Connection refused')': /raw?location=
[2024-12-23T09:09:10.610+0000] {connectionpool.py:874} WARNING - Retrying (Retry(total=2, connect=None, read=None, redirect=None, status=None)) after connection broken by 'NewConnectionError('<urllib3.connection.HTTPConnection object at 0x7f3993252ab0>: Failed to establish a new connection: [Errno 111] Connection refused')': /raw?location=
[2024-12-23T09:09:12.212+0000] {connectionpool.py:874} WARNING - Retrying (Retry(total=1, connect=None, read=None, redirect=None, status=None)) after connection broken by 'NewConnectionError('<urllib3.connection.HTTPConnection object at 0x7f3993253050>: Failed to establish a new connection: [Errno 111] Connection refused')': /raw?location=
[2024-12-23T09:09:15.414+0000] {connectionpool.py:874} WARNING - Retrying (Retry(total=0, connect=None, read=None, redirect=None, status=None)) after connection broken by 'NewConnectionError('<urllib3.connection.HTTPConnection object at 0x7f3993253350>: Failed to establish a new connection: [Errno 111] Connection refused')': /raw?location=
[2024-12-23T09:09:15.416+0000] {taskinstance.py:441} INFO - ::group::Post task execution logs
[2024-12-23T09:09:15.417+0000] {taskinstance.py:2905} ERROR - Task failed with exception
Traceback (most recent call last):
  File "/home/airflow/.local/lib/python3.12/site-packages/urllib3/connection.py", line 198, in _new_conn
    sock = connection.create_connection(
           ^^^^^^^^^^^^^^^^^^^^^^^^^^^^^
  File "/home/airflow/.local/lib/python3.12/site-packages/urllib3/util/connection.py", line 85, in create_connection
    raise err
  File "/home/airflow/.local/lib/python3.12/site-packages/urllib3/util/connection.py", line 73, in create_connection
    sock.connect(sa)
ConnectionRefusedError: [Errno 111] Connection refused

The above exception was the direct cause of the following exception:

Traceback (most recent call last):
  File "/home/airflow/.local/lib/python3.12/site-packages/urllib3/connectionpool.py", line 793, in urlopen
    response = self._make_request(
               ^^^^^^^^^^^^^^^^^^^
  File "/home/airflow/.local/lib/python3.12/site-packages/urllib3/connectionpool.py", line 496, in _make_request
    conn.request(
  File "/home/airflow/.local/lib/python3.12/site-packages/urllib3/connection.py", line 400, in request
    self.endheaders()
  File "/usr/local/lib/python3.12/http/client.py", line 1331, in endheaders
    self._send_output(message_body, encode_chunked=encode_chunked)
  File "/usr/local/lib/python3.12/http/client.py", line 1091, in _send_output
    self.send(msg)
  File "/usr/local/lib/python3.12/http/client.py", line 1035, in send
    self.connect()
  File "/home/airflow/.local/lib/python3.12/site-packages/urllib3/connection.py", line 238, in connect
    self.sock = self._new_conn()
                ^^^^^^^^^^^^^^^^
  File "/home/airflow/.local/lib/python3.12/site-packages/urllib3/connection.py", line 213, in _new_conn
    raise NewConnectionError(
urllib3.exceptions.NewConnectionError: <urllib3.connection.HTTPConnection object at 0x7f39932537d0>: Failed to establish a new connection: [Errno 111] Connection refused

The above exception was the direct cause of the following exception:

Traceback (most recent call last):
  File "/home/airflow/.local/lib/python3.12/site-packages/airflow/models/taskinstance.py", line 465, in _execute_task
    result = _execute_callable(context=context, **execute_callable_kwargs)
             ^^^^^^^^^^^^^^^^^^^^^^^^^^^^^^^^^^^^^^^^^^^^^^^^^^^^^^^^^^^^^
  File "/home/airflow/.local/lib/python3.12/site-packages/airflow/models/taskinstance.py", line 432, in _execute_callable
    return execute_callable(context=context, **execute_callable_kwargs)
           ^^^^^^^^^^^^^^^^^^^^^^^^^^^^^^^^^^^^^^^^^^^^^^^^^^^^^^^^^^^^
  File "/home/airflow/.local/lib/python3.12/site-packages/airflow/models/baseoperator.py", line 401, in wrapper
    return func(self, *args, **kwargs)
           ^^^^^^^^^^^^^^^^^^^^^^^^^^^
  File "/home/airflow/.local/lib/python3.12/site-packages/airflow/operators/python.py", line 235, in execute
    return_value = self.execute_callable()
                   ^^^^^^^^^^^^^^^^^^^^^^^
  File "/home/airflow/.local/lib/python3.12/site-packages/airflow/operators/python.py", line 252, in execute_callable
    return self.python_callable(*self.op_args, **self.op_kwargs)
           ^^^^^^^^^^^^^^^^^^^^^^^^^^^^^^^^^^^^^^^^^^^^^^^^^^^^^
  File "/opt/airflow/dags/stream_processing/streaming_image_to_dl.py", line 49, in image_to_dl
    minio_client.create_bucket(args.bucket_name)
  File "/opt/airflow/dags/utils/minio_utils.py", line 23, in create_bucket
    found = client.bucket_exists(bucket_name=bucket_name)
            ^^^^^^^^^^^^^^^^^^^^^^^^^^^^^^^^^^^^^^^^^^^^^
  File "/home/airflow/.local/lib/python3.12/site-packages/minio/api.py", line 697, in bucket_exists
    self._execute("HEAD", bucket_name)
  File "/home/airflow/.local/lib/python3.12/site-packages/minio/api.py", line 438, in _execute
    region = self._get_region(bucket_name)
             ^^^^^^^^^^^^^^^^^^^^^^^^^^^^^
  File "/home/airflow/.local/lib/python3.12/site-packages/minio/api.py", line 495, in _get_region
    response = self._url_open(
               ^^^^^^^^^^^^^^^
  File "/home/airflow/.local/lib/python3.12/site-packages/minio/api.py", line 303, in _url_open
    response = self._http.urlopen(
               ^^^^^^^^^^^^^^^^^^^
  File "/home/airflow/.local/lib/python3.12/site-packages/urllib3/poolmanager.py", line 444, in urlopen
    response = conn.urlopen(method, u.request_uri, **kw)
               ^^^^^^^^^^^^^^^^^^^^^^^^^^^^^^^^^^^^^^^^^
  File "/home/airflow/.local/lib/python3.12/site-packages/urllib3/connectionpool.py", line 877, in urlopen
    return self.urlopen(
           ^^^^^^^^^^^^^
  File "/home/airflow/.local/lib/python3.12/site-packages/urllib3/connectionpool.py", line 877, in urlopen
    return self.urlopen(
           ^^^^^^^^^^^^^
  File "/home/airflow/.local/lib/python3.12/site-packages/urllib3/connectionpool.py", line 877, in urlopen
    return self.urlopen(
           ^^^^^^^^^^^^^
  [Previous line repeated 2 more times]
  File "/home/airflow/.local/lib/python3.12/site-packages/urllib3/connectionpool.py", line 847, in urlopen
    retries = retries.increment(
              ^^^^^^^^^^^^^^^^^^
  File "/home/airflow/.local/lib/python3.12/site-packages/urllib3/util/retry.py", line 515, in increment
    raise MaxRetryError(_pool, url, reason) from reason  # type: ignore[arg-type]
    ^^^^^^^^^^^^^^^^^^^^^^^^^^^^^^^^^^^^^^^^^^^^^^^^^^^
urllib3.exceptions.MaxRetryError: HTTPConnectionPool(host='localhost', port=9000): Max retries exceeded with url: /raw?location= (Caused by NewConnectionError('<urllib3.connection.HTTPConnection object at 0x7f39932537d0>: Failed to establish a new connection: [Errno 111] Connection refused'))
[2024-12-23T09:09:15.438+0000] {taskinstance.py:1206} INFO - Marking task as FAILED. dag_id=streaming_pipeline, task_id=image_to_datalake, run_id=manual__2024-12-23T09:09:05.347904+00:00, execution_date=20241223T090905, start_date=20241223T090909, end_date=20241223T090915
[2024-12-23T09:09:15.459+0000] {standard_task_runner.py:110} ERROR - Failed to execute job 73 for task image_to_datalake (HTTPConnectionPool(host='localhost', port=9000): Max retries exceeded with url: /raw?location= (Caused by NewConnectionError('<urllib3.connection.HTTPConnection object at 0x7f39932537d0>: Failed to establish a new connection: [Errno 111] Connection refused')); 2376)
[2024-12-23T09:09:15.486+0000] {local_task_job_runner.py:240} INFO - Task exited with return code 1
[2024-12-23T09:09:15.495+0000] {local_task_job_runner.py:222} INFO - ::endgroup::
