[2024-12-23T10:51:47.133+0000] {local_task_job_runner.py:120} INFO - ::group::Pre task execution logs
[2024-12-23T10:51:47.173+0000] {taskinstance.py:2076} INFO - Dependencies all met for dep_context=non-requeueable deps ti=<TaskInstance: streaming_pipeline.speech_to_datalake manual__2024-12-23T10:51:43.030229+00:00 [queued]>
[2024-12-23T10:51:47.185+0000] {taskinstance.py:2076} INFO - Dependencies all met for dep_context=requeueable deps ti=<TaskInstance: streaming_pipeline.speech_to_datalake manual__2024-12-23T10:51:43.030229+00:00 [queued]>
[2024-12-23T10:51:47.186+0000] {taskinstance.py:2306} INFO - Starting attempt 1 of 1
[2024-12-23T10:51:47.203+0000] {taskinstance.py:2330} INFO - Executing <Task(PythonOperator): speech_to_datalake> on 2024-12-23 10:51:43.030229+00:00
[2024-12-23T10:51:47.210+0000] {standard_task_runner.py:63} INFO - Started process 540 to run task
[2024-12-23T10:51:47.214+0000] {standard_task_runner.py:90} INFO - Running: ['***', 'tasks', 'run', 'streaming_pipeline', 'speech_to_datalake', 'manual__2024-12-23T10:51:43.030229+00:00', '--job-id', '85', '--raw', '--subdir', 'DAGS_FOLDER/pipline_stream.py', '--cfg-path', '/tmp/tmp8g0lus9o']
[2024-12-23T10:51:47.217+0000] {standard_task_runner.py:91} INFO - Job 85: Subtask speech_to_datalake
[2024-12-23T10:51:47.292+0000] {task_command.py:426} INFO - Running <TaskInstance: streaming_pipeline.speech_to_datalake manual__2024-12-23T10:51:43.030229+00:00 [running]> on host 0b4a5bf62610
[2024-12-23T10:51:47.411+0000] {taskinstance.py:2648} INFO - Exporting env vars: AIRFLOW_CTX_DAG_OWNER='***' AIRFLOW_CTX_DAG_ID='streaming_pipeline' AIRFLOW_CTX_TASK_ID='speech_to_datalake' AIRFLOW_CTX_EXECUTION_DATE='2024-12-23T10:51:43.030229+00:00' AIRFLOW_CTX_TRY_NUMBER='1' AIRFLOW_CTX_DAG_RUN_ID='manual__2024-12-23T10:51:43.030229+00:00'
[2024-12-23T10:51:47.414+0000] {taskinstance.py:430} INFO - ::endgroup::
[2024-12-23T10:52:08.484+0000] {connectionpool.py:874} WARNING - Retrying (Retry(total=4, connect=None, read=None, redirect=None, status=None)) after connection broken by 'NewConnectionError('<urllib3.connection.HTTPConnection object at 0x7f7bb0ac79e0>: Failed to establish a new connection: [Errno 111] Connection refused')': /raw?location=
[2024-12-23T10:52:29.934+0000] {connectionpool.py:874} WARNING - Retrying (Retry(total=3, connect=None, read=None, redirect=None, status=None)) after connection broken by 'NewConnectionError('<urllib3.connection.HTTPConnection object at 0x7f7bb0af8080>: Failed to establish a new connection: [Errno 111] Connection refused')': /raw?location=
[2024-12-23T10:52:51.801+0000] {connectionpool.py:874} WARNING - Retrying (Retry(total=2, connect=None, read=None, redirect=None, status=None)) after connection broken by 'NewConnectionError('<urllib3.connection.HTTPConnection object at 0x7f7bb0af84a0>: Failed to establish a new connection: [Errno 111] Connection refused')': /raw?location=
[2024-12-23T10:53:14.445+0000] {connectionpool.py:874} WARNING - Retrying (Retry(total=1, connect=None, read=None, redirect=None, status=None)) after connection broken by 'NewConnectionError('<urllib3.connection.HTTPConnection object at 0x7f7bb0af8a10>: Failed to establish a new connection: [Errno 111] Connection refused')': /raw?location=
[2024-12-23T10:53:38.355+0000] {local_task_job_runner.py:310} WARNING - State of this instance has been externally set to None. Terminating instance.
[2024-12-23T10:53:38.357+0000] {local_task_job_runner.py:222} INFO - ::endgroup::
[2024-12-23T10:53:38.360+0000] {process_utils.py:132} INFO - Sending 15 to group 540. PIDs of all processes in the group: [540]
[2024-12-23T10:53:38.361+0000] {process_utils.py:87} INFO - Sending the signal 15 to group 540
[2024-12-23T10:53:38.362+0000] {taskinstance.py:2611} ERROR - Received SIGTERM. Terminating subprocesses.
[2024-12-23T10:53:38.363+0000] {taskinstance.py:441} INFO - ::group::Post task execution logs
[2024-12-23T10:53:38.375+0000] {taskinstance.py:2905} ERROR - Task failed with exception
Traceback (most recent call last):
  File "/home/airflow/.local/lib/python3.12/site-packages/urllib3/connection.py", line 198, in _new_conn
    sock = connection.create_connection(
           ^^^^^^^^^^^^^^^^^^^^^^^^^^^^^
  File "/home/airflow/.local/lib/python3.12/site-packages/urllib3/util/connection.py", line 85, in create_connection
    raise err
  File "/home/airflow/.local/lib/python3.12/site-packages/urllib3/util/connection.py", line 73, in create_connection
    sock.connect(sa)
ConnectionRefusedError: [Errno 111] Connection refused

The above exception was the direct cause of the following exception:

Traceback (most recent call last):
  File "/home/airflow/.local/lib/python3.12/site-packages/urllib3/connectionpool.py", line 793, in urlopen
    response = self._make_request(
               ^^^^^^^^^^^^^^^^^^^
  File "/home/airflow/.local/lib/python3.12/site-packages/urllib3/connectionpool.py", line 496, in _make_request
    conn.request(
  File "/home/airflow/.local/lib/python3.12/site-packages/urllib3/connection.py", line 400, in request
    self.endheaders()
  File "/usr/local/lib/python3.12/http/client.py", line 1331, in endheaders
    self._send_output(message_body, encode_chunked=encode_chunked)
  File "/usr/local/lib/python3.12/http/client.py", line 1091, in _send_output
    self.send(msg)
  File "/usr/local/lib/python3.12/http/client.py", line 1035, in send
    self.connect()
  File "/home/airflow/.local/lib/python3.12/site-packages/urllib3/connection.py", line 238, in connect
    self.sock = self._new_conn()
                ^^^^^^^^^^^^^^^^
  File "/home/airflow/.local/lib/python3.12/site-packages/urllib3/connection.py", line 213, in _new_conn
    raise NewConnectionError(
urllib3.exceptions.NewConnectionError: <urllib3.connection.HTTPConnection object at 0x7f7bb0af8ec0>: Failed to establish a new connection: [Errno 111] Connection refused

During handling of the above exception, another exception occurred:

Traceback (most recent call last):
  File "/home/airflow/.local/lib/python3.12/site-packages/airflow/models/taskinstance.py", line 465, in _execute_task
    result = _execute_callable(context=context, **execute_callable_kwargs)
             ^^^^^^^^^^^^^^^^^^^^^^^^^^^^^^^^^^^^^^^^^^^^^^^^^^^^^^^^^^^^^
  File "/home/airflow/.local/lib/python3.12/site-packages/airflow/models/taskinstance.py", line 432, in _execute_callable
    return execute_callable(context=context, **execute_callable_kwargs)
           ^^^^^^^^^^^^^^^^^^^^^^^^^^^^^^^^^^^^^^^^^^^^^^^^^^^^^^^^^^^^
  File "/home/airflow/.local/lib/python3.12/site-packages/airflow/models/baseoperator.py", line 401, in wrapper
    return func(self, *args, **kwargs)
           ^^^^^^^^^^^^^^^^^^^^^^^^^^^
  File "/home/airflow/.local/lib/python3.12/site-packages/airflow/operators/python.py", line 235, in execute
    return_value = self.execute_callable()
                   ^^^^^^^^^^^^^^^^^^^^^^^
  File "/home/airflow/.local/lib/python3.12/site-packages/airflow/operators/python.py", line 252, in execute_callable
    return self.python_callable(*self.op_args, **self.op_kwargs)
           ^^^^^^^^^^^^^^^^^^^^^^^^^^^^^^^^^^^^^^^^^^^^^^^^^^^^^
  File "/opt/airflow/dags/stream_processing/streaming_speech_to_dl.py", line 51, in speech_to_dl
    minio_client.create_bucket(args.bucket_name)
  File "/opt/airflow/dags/utils/minio_utils.py", line 23, in create_bucket
    found = client.bucket_exists(bucket_name=bucket_name)
            ^^^^^^^^^^^^^^^^^^^^^^^^^^^^^^^^^^^^^^^^^^^^^
  File "/home/airflow/.local/lib/python3.12/site-packages/minio/api.py", line 697, in bucket_exists
    self._execute("HEAD", bucket_name)
  File "/home/airflow/.local/lib/python3.12/site-packages/minio/api.py", line 438, in _execute
    region = self._get_region(bucket_name)
             ^^^^^^^^^^^^^^^^^^^^^^^^^^^^^
  File "/home/airflow/.local/lib/python3.12/site-packages/minio/api.py", line 495, in _get_region
    response = self._url_open(
               ^^^^^^^^^^^^^^^
  File "/home/airflow/.local/lib/python3.12/site-packages/minio/api.py", line 303, in _url_open
    response = self._http.urlopen(
               ^^^^^^^^^^^^^^^^^^^
  File "/home/airflow/.local/lib/python3.12/site-packages/urllib3/poolmanager.py", line 444, in urlopen
    response = conn.urlopen(method, u.request_uri, **kw)
               ^^^^^^^^^^^^^^^^^^^^^^^^^^^^^^^^^^^^^^^^^
  File "/home/airflow/.local/lib/python3.12/site-packages/urllib3/connectionpool.py", line 877, in urlopen
    return self.urlopen(
           ^^^^^^^^^^^^^
  File "/home/airflow/.local/lib/python3.12/site-packages/urllib3/connectionpool.py", line 877, in urlopen
    return self.urlopen(
           ^^^^^^^^^^^^^
  File "/home/airflow/.local/lib/python3.12/site-packages/urllib3/connectionpool.py", line 877, in urlopen
    return self.urlopen(
           ^^^^^^^^^^^^^
  [Previous line repeated 1 more time]
  File "/home/airflow/.local/lib/python3.12/site-packages/urllib3/connectionpool.py", line 850, in urlopen
    retries.sleep()
  File "/home/airflow/.local/lib/python3.12/site-packages/urllib3/util/retry.py", line 359, in sleep
    self._sleep_backoff()
  File "/home/airflow/.local/lib/python3.12/site-packages/urllib3/util/retry.py", line 343, in _sleep_backoff
    time.sleep(backoff)
  File "/home/airflow/.local/lib/python3.12/site-packages/airflow/models/taskinstance.py", line 2613, in signal_handler
    raise AirflowTaskTerminated("Task received SIGTERM signal")
airflow.exceptions.AirflowTaskTerminated: Task received SIGTERM signal
[2024-12-23T10:53:38.397+0000] {taskinstance.py:1206} INFO - Marking task as FAILED. dag_id=streaming_pipeline, task_id=speech_to_datalake, run_id=manual__2024-12-23T10:51:43.030229+00:00, execution_date=20241223T105143, start_date=20241223T105147, end_date=20241223T105338
[2024-12-23T10:53:38.419+0000] {standard_task_runner.py:110} ERROR - Failed to execute job 85 for task speech_to_datalake ((psycopg2.errors.ForeignKeyViolation) insert or update on table "task_fail" violates foreign key constraint "task_fail_ti_fkey"
DETAIL:  Key (dag_id, task_id, run_id, map_index)=(streaming_pipeline, speech_to_datalake, manual__2024-12-23T10:51:43.030229+00:00, -1) is not present in table "task_instance".

[SQL: INSERT INTO task_fail (task_id, dag_id, run_id, map_index, start_date, end_date, duration) VALUES (%(task_id)s, %(dag_id)s, %(run_id)s, %(map_index)s, %(start_date)s, %(end_date)s, %(duration)s) RETURNING task_fail.id]
[parameters: {'task_id': 'speech_to_datalake', 'dag_id': 'streaming_pipeline', 'run_id': 'manual__2024-12-23T10:51:43.030229+00:00', 'map_index': -1, 'start_date': datetime.datetime(2024, 12, 23, 10, 51, 47, 174352, tzinfo=Timezone('UTC')), 'end_date': datetime.datetime(2024, 12, 23, 10, 53, 38, 396754, tzinfo=Timezone('UTC')), 'duration': 111}]
(Background on this error at: https://sqlalche.me/e/14/gkpj); 540)
[2024-12-23T10:53:38.454+0000] {process_utils.py:80} INFO - Process psutil.Process(pid=540, status='terminated', exitcode=1, started='10:51:46') (540) terminated with exit code 1
