[2024-12-24T18:16:07.186+0000] {local_task_job_runner.py:120} INFO - ::group::Pre task execution logs
[2024-12-24T18:16:07.220+0000] {taskinstance.py:2076} INFO - Dependencies all met for dep_context=non-requeueable deps ti=<TaskInstance: pipeline_batch_visualize.transform_save_to_bigquery manual__2024-12-24T18:15:27.596663+00:00 [queued]>
[2024-12-24T18:16:07.232+0000] {taskinstance.py:2076} INFO - Dependencies all met for dep_context=requeueable deps ti=<TaskInstance: pipeline_batch_visualize.transform_save_to_bigquery manual__2024-12-24T18:15:27.596663+00:00 [queued]>
[2024-12-24T18:16:07.233+0000] {taskinstance.py:2306} INFO - Starting attempt 1 of 1
[2024-12-24T18:16:07.250+0000] {taskinstance.py:2330} INFO - Executing <Task(PythonOperator): transform_save_to_bigquery> on 2024-12-24 18:15:27.596663+00:00
[2024-12-24T18:16:07.257+0000] {standard_task_runner.py:63} INFO - Started process 3804 to run task
[2024-12-24T18:16:07.259+0000] {standard_task_runner.py:90} INFO - Running: ['***', 'tasks', 'run', 'pipeline_batch_visualize', 'transform_save_to_bigquery', 'manual__2024-12-24T18:15:27.596663+00:00', '--job-id', '328', '--raw', '--subdir', 'DAGS_FOLDER/pipeline_batch_visualize.py', '--cfg-path', '/tmp/tmp380i9cu5']
[2024-12-24T18:16:07.261+0000] {standard_task_runner.py:91} INFO - Job 328: Subtask transform_save_to_bigquery
[2024-12-24T18:16:07.314+0000] {task_command.py:426} INFO - Running <TaskInstance: pipeline_batch_visualize.transform_save_to_bigquery manual__2024-12-24T18:15:27.596663+00:00 [running]> on host 0b4a5bf62610
[2024-12-24T18:16:07.423+0000] {taskinstance.py:2648} INFO - Exporting env vars: AIRFLOW_CTX_DAG_OWNER='***' AIRFLOW_CTX_DAG_ID='pipeline_batch_visualize' AIRFLOW_CTX_TASK_ID='transform_save_to_bigquery' AIRFLOW_CTX_EXECUTION_DATE='2024-12-24T18:15:27.596663+00:00' AIRFLOW_CTX_TRY_NUMBER='1' AIRFLOW_CTX_DAG_RUN_ID='manual__2024-12-24T18:15:27.596663+00:00'
[2024-12-24T18:16:07.425+0000] {taskinstance.py:430} INFO - ::endgroup::
[2024-12-24T18:16:17.910+0000] {upload_to_bigquery.py:157} INFO - Spark session successfully created!
[2024-12-24T18:16:17.919+0000] {upload_to_bigquery.py:211} INFO - Google BigQuery configuration is created successfully
[2024-12-24T18:16:17.927+0000] {upload_to_bigquery.py:188} INFO - MinIO configuration is created successfully
[2024-12-24T18:16:27.133+0000] {load_and_transform.py:385} INFO - Done load taxi lookup
[2024-12-24T18:16:28.954+0000] {_metadata.py:139} WARNING - Compute Engine Metadata server unavailable on attempt 1 of 3. Reason: [Errno 111] Connection refused
[2024-12-24T18:16:28.957+0000] {_metadata.py:139} WARNING - Compute Engine Metadata server unavailable on attempt 2 of 3. Reason: [Errno 111] Connection refused
[2024-12-24T18:16:28.960+0000] {_metadata.py:139} WARNING - Compute Engine Metadata server unavailable on attempt 3 of 3. Reason: [Errno 111] Connection refused
[2024-12-24T18:16:28.961+0000] {_default.py:338} WARNING - Authentication failed using Compute Engine authentication due to unavailable metadata server.
[2024-12-24T18:16:28.962+0000] {taskinstance.py:441} INFO - ::group::Post task execution logs
[2024-12-24T18:16:28.963+0000] {taskinstance.py:2905} ERROR - Task failed with exception
Traceback (most recent call last):
  File "/home/airflow/.local/lib/python3.12/site-packages/airflow/models/taskinstance.py", line 465, in _execute_task
    result = _execute_callable(context=context, **execute_callable_kwargs)
             ^^^^^^^^^^^^^^^^^^^^^^^^^^^^^^^^^^^^^^^^^^^^^^^^^^^^^^^^^^^^^
  File "/home/airflow/.local/lib/python3.12/site-packages/airflow/models/taskinstance.py", line 432, in _execute_callable
    return execute_callable(context=context, **execute_callable_kwargs)
           ^^^^^^^^^^^^^^^^^^^^^^^^^^^^^^^^^^^^^^^^^^^^^^^^^^^^^^^^^^^^
  File "/home/airflow/.local/lib/python3.12/site-packages/airflow/models/baseoperator.py", line 401, in wrapper
    return func(self, *args, **kwargs)
           ^^^^^^^^^^^^^^^^^^^^^^^^^^^
  File "/home/airflow/.local/lib/python3.12/site-packages/airflow/operators/python.py", line 235, in execute
    return_value = self.execute_callable()
                   ^^^^^^^^^^^^^^^^^^^^^^^
  File "/home/airflow/.local/lib/python3.12/site-packages/airflow/operators/python.py", line 252, in execute_callable
    return self.python_callable(*self.op_args, **self.op_kwargs)
           ^^^^^^^^^^^^^^^^^^^^^^^^^^^^^^^^^^^^^^^^^^^^^^^^^^^^^
  File "/opt/airflow/dags/batch_processing/load_and_transform.py", line 388, in load_transform_save
    create_table_bg(
  File "/opt/airflow/dags/batch_processing/upload_to_bigquery.py", line 308, in create_table_bg
    client = bigquery.Client(project=project_id)
             ^^^^^^^^^^^^^^^^^^^^^^^^^^^^^^^^^^^
  File "/home/airflow/.local/lib/python3.12/site-packages/google/cloud/bigquery/client.py", line 241, in __init__
    super(Client, self).__init__(
  File "/home/airflow/.local/lib/python3.12/site-packages/google/cloud/client/__init__.py", line 321, in __init__
    Client.__init__(
  File "/home/airflow/.local/lib/python3.12/site-packages/google/cloud/client/__init__.py", line 178, in __init__
    credentials, _ = google.auth.default(scopes=scopes)
                     ^^^^^^^^^^^^^^^^^^^^^^^^^^^^^^^^^^
  File "/home/airflow/.local/lib/python3.12/site-packages/google/auth/_default.py", line 691, in default
    raise exceptions.DefaultCredentialsError(_CLOUD_SDK_MISSING_CREDENTIALS)
google.auth.exceptions.DefaultCredentialsError: Your default credentials were not found. To set up Application Default Credentials, see https://cloud.google.com/docs/authentication/external/set-up-adc for more information.
[2024-12-24T18:16:28.979+0000] {taskinstance.py:1206} INFO - Marking task as FAILED. dag_id=pipeline_batch_visualize, task_id=transform_save_to_bigquery, run_id=manual__2024-12-24T18:15:27.596663+00:00, execution_date=20241224T181527, start_date=20241224T181607, end_date=20241224T181628
[2024-12-24T18:16:28.997+0000] {standard_task_runner.py:110} ERROR - Failed to execute job 328 for task transform_save_to_bigquery (Your default credentials were not found. To set up Application Default Credentials, see https://cloud.google.com/docs/authentication/external/set-up-adc for more information.; 3804)
[2024-12-24T18:16:29.026+0000] {local_task_job_runner.py:240} INFO - Task exited with return code 1
[2024-12-24T18:16:29.053+0000] {taskinstance.py:3503} INFO - 0 downstream tasks scheduled from follow-on schedule check
[2024-12-24T18:16:29.058+0000] {local_task_job_runner.py:222} INFO - ::endgroup::
