[2024-12-24T18:42:02.279+0000] {local_task_job_runner.py:120} INFO - ::group::Pre task execution logs
[2024-12-24T18:42:02.308+0000] {taskinstance.py:2076} INFO - Dependencies all met for dep_context=non-requeueable deps ti=<TaskInstance: pipeline_batch_visualize.start manual__2024-12-24T18:42:00.591974+00:00 [queued]>
[2024-12-24T18:42:02.318+0000] {taskinstance.py:2076} INFO - Dependencies all met for dep_context=requeueable deps ti=<TaskInstance: pipeline_batch_visualize.start manual__2024-12-24T18:42:00.591974+00:00 [queued]>
[2024-12-24T18:42:02.319+0000] {taskinstance.py:2306} INFO - Starting attempt 1 of 1
[2024-12-24T18:42:02.337+0000] {taskinstance.py:2330} INFO - Executing <Task(PythonOperator): start> on 2024-12-24 18:42:00.591974+00:00
[2024-12-24T18:42:02.343+0000] {standard_task_runner.py:63} INFO - Started process 8748 to run task
[2024-12-24T18:42:02.346+0000] {standard_task_runner.py:90} INFO - Running: ['***', 'tasks', 'run', 'pipeline_batch_visualize', 'start', 'manual__2024-12-24T18:42:00.591974+00:00', '--job-id', '338', '--raw', '--subdir', 'DAGS_FOLDER/pipeline_batch_visualize.py', '--cfg-path', '/tmp/tmpcdi0oo2u']
[2024-12-24T18:42:02.348+0000] {standard_task_runner.py:91} INFO - Job 338: Subtask start
[2024-12-24T18:42:02.400+0000] {task_command.py:426} INFO - Running <TaskInstance: pipeline_batch_visualize.start manual__2024-12-24T18:42:00.591974+00:00 [running]> on host 0b4a5bf62610
[2024-12-24T18:42:02.489+0000] {taskinstance.py:2648} INFO - Exporting env vars: AIRFLOW_CTX_DAG_OWNER='***' AIRFLOW_CTX_DAG_ID='pipeline_batch_visualize' AIRFLOW_CTX_TASK_ID='start' AIRFLOW_CTX_EXECUTION_DATE='2024-12-24T18:42:00.591974+00:00' AIRFLOW_CTX_TRY_NUMBER='1' AIRFLOW_CTX_DAG_RUN_ID='manual__2024-12-24T18:42:00.591974+00:00'
[2024-12-24T18:42:02.490+0000] {taskinstance.py:430} INFO - ::endgroup::
[2024-12-24T18:42:02.504+0000] {logging_mixin.py:188} WARNING - --- Logging error ---
[2024-12-24T18:42:02.506+0000] {logging_mixin.py:188} WARNING - Traceback (most recent call last):
[2024-12-24T18:42:02.507+0000] {logging_mixin.py:188} WARNING -   File "/usr/local/lib/python3.12/logging/__init__.py", line 1160, in emit
    msg = self.format(record)
          ^^^^^^^^^^^^^^^^^^^
[2024-12-24T18:42:02.507+0000] {logging_mixin.py:188} WARNING -   File "/usr/local/lib/python3.12/logging/__init__.py", line 999, in format
    return fmt.format(record)
           ^^^^^^^^^^^^^^^^^^
[2024-12-24T18:42:02.508+0000] {logging_mixin.py:188} WARNING -   File "/usr/local/lib/python3.12/logging/__init__.py", line 703, in format
    record.message = record.getMessage()
                     ^^^^^^^^^^^^^^^^^^^
[2024-12-24T18:42:02.508+0000] {logging_mixin.py:188} WARNING -   File "/usr/local/lib/python3.12/logging/__init__.py", line 392, in getMessage
    msg = msg % self.args
          ~~~~^~~~~~~~~~~
[2024-12-24T18:42:02.509+0000] {logging_mixin.py:188} WARNING - TypeError: not all arguments converted during string formatting
[2024-12-24T18:42:02.510+0000] {logging_mixin.py:188} WARNING - Call stack:
[2024-12-24T18:42:02.517+0000] {logging_mixin.py:188} WARNING -   File "/home/***/.local/bin/***", line 8, in <module>
    sys.exit(main())
[2024-12-24T18:42:02.518+0000] {logging_mixin.py:188} WARNING -   File "/home/***/.local/lib/python3.12/site-packages/***/__main__.py", line 58, in main
    args.func(args)
[2024-12-24T18:42:02.519+0000] {logging_mixin.py:188} WARNING -   File "/home/***/.local/lib/python3.12/site-packages/***/cli/cli_config.py", line 49, in command
    return func(*args, **kwargs)
[2024-12-24T18:42:02.520+0000] {logging_mixin.py:188} WARNING -   File "/home/***/.local/lib/python3.12/site-packages/***/utils/cli.py", line 114, in wrapper
    return f(*args, **kwargs)
[2024-12-24T18:42:02.521+0000] {logging_mixin.py:188} WARNING -   File "/home/***/.local/lib/python3.12/site-packages/***/utils/providers_configuration_loader.py", line 55, in wrapped_function
    return func(*args, **kwargs)
[2024-12-24T18:42:02.522+0000] {logging_mixin.py:188} WARNING -   File "/home/***/.local/lib/python3.12/site-packages/***/cli/commands/scheduler_command.py", line 58, in scheduler
    run_command_with_daemon_option(
[2024-12-24T18:42:02.522+0000] {logging_mixin.py:188} WARNING -   File "/home/***/.local/lib/python3.12/site-packages/***/cli/commands/daemon_utils.py", line 85, in run_command_with_daemon_option
    callback()
[2024-12-24T18:42:02.523+0000] {logging_mixin.py:188} WARNING -   File "/home/***/.local/lib/python3.12/site-packages/***/cli/commands/scheduler_command.py", line 61, in <lambda>
    callback=lambda: _run_scheduler_job(args),
[2024-12-24T18:42:02.524+0000] {logging_mixin.py:188} WARNING -   File "/home/***/.local/lib/python3.12/site-packages/***/cli/commands/scheduler_command.py", line 49, in _run_scheduler_job
    run_job(job=job_runner.job, execute_callable=job_runner._execute)
[2024-12-24T18:42:02.524+0000] {logging_mixin.py:188} WARNING -   File "/home/***/.local/lib/python3.12/site-packages/***/utils/session.py", line 79, in wrapper
    return func(*args, session=session, **kwargs)
[2024-12-24T18:42:02.525+0000] {logging_mixin.py:188} WARNING -   File "/home/***/.local/lib/python3.12/site-packages/***/jobs/job.py", line 402, in run_job
    return execute_job(job, execute_callable=execute_callable)
[2024-12-24T18:42:02.526+0000] {logging_mixin.py:188} WARNING -   File "/home/***/.local/lib/python3.12/site-packages/***/jobs/job.py", line 431, in execute_job
    ret = execute_callable()
[2024-12-24T18:42:02.526+0000] {logging_mixin.py:188} WARNING -   File "/home/***/.local/lib/python3.12/site-packages/***/jobs/scheduler_job_runner.py", line 834, in _execute
    self.job.executor.start()
[2024-12-24T18:42:02.527+0000] {logging_mixin.py:188} WARNING -   File "/home/***/.local/lib/python3.12/site-packages/***/executors/local_executor.py", line 373, in start
    self.impl.start()
[2024-12-24T18:42:02.527+0000] {logging_mixin.py:188} WARNING -   File "/home/***/.local/lib/python3.12/site-packages/***/executors/local_executor.py", line 312, in start
    worker.start()
[2024-12-24T18:42:02.528+0000] {logging_mixin.py:188} WARNING -   File "/usr/local/lib/python3.12/multiprocessing/process.py", line 121, in start
    self._popen = self._Popen(self)
[2024-12-24T18:42:02.529+0000] {logging_mixin.py:188} WARNING -   File "/usr/local/lib/python3.12/multiprocessing/context.py", line 224, in _Popen
    return _default_context.get_context().Process._Popen(process_obj)
[2024-12-24T18:42:02.529+0000] {logging_mixin.py:188} WARNING -   File "/usr/local/lib/python3.12/multiprocessing/context.py", line 282, in _Popen
    return Popen(process_obj)
[2024-12-24T18:42:02.529+0000] {logging_mixin.py:188} WARNING -   File "/usr/local/lib/python3.12/multiprocessing/popen_fork.py", line 19, in __init__
    self._launch(process_obj)
[2024-12-24T18:42:02.530+0000] {logging_mixin.py:188} WARNING -   File "/usr/local/lib/python3.12/multiprocessing/popen_fork.py", line 71, in _launch
    code = process_obj._bootstrap(parent_sentinel=child_r)
[2024-12-24T18:42:02.530+0000] {logging_mixin.py:188} WARNING -   File "/usr/local/lib/python3.12/multiprocessing/process.py", line 314, in _bootstrap
    self.run()
[2024-12-24T18:42:02.531+0000] {logging_mixin.py:188} WARNING -   File "/home/***/.local/lib/python3.12/site-packages/***/executors/local_executor.py", line 78, in run
    return super().run()
[2024-12-24T18:42:02.531+0000] {logging_mixin.py:188} WARNING -   File "/usr/local/lib/python3.12/multiprocessing/process.py", line 108, in run
    self._target(*self._args, **self._kwargs)
[2024-12-24T18:42:02.532+0000] {logging_mixin.py:188} WARNING -   File "/home/***/.local/lib/python3.12/site-packages/***/executors/local_executor.py", line 202, in do_work
    self.execute_work(key=key, command=command)
[2024-12-24T18:42:02.532+0000] {logging_mixin.py:188} WARNING -   File "/home/***/.local/lib/python3.12/site-packages/***/executors/local_executor.py", line 95, in execute_work
    state = self._execute_work_in_fork(command)
[2024-12-24T18:42:02.533+0000] {logging_mixin.py:188} WARNING -   File "/home/***/.local/lib/python3.12/site-packages/***/executors/local_executor.py", line 135, in _execute_work_in_fork
    args.func(args)
[2024-12-24T18:42:02.533+0000] {logging_mixin.py:188} WARNING -   File "/home/***/.local/lib/python3.12/site-packages/***/cli/cli_config.py", line 49, in command
    return func(*args, **kwargs)
[2024-12-24T18:42:02.534+0000] {logging_mixin.py:188} WARNING -   File "/home/***/.local/lib/python3.12/site-packages/***/utils/cli.py", line 114, in wrapper
    return f(*args, **kwargs)
[2024-12-24T18:42:02.535+0000] {logging_mixin.py:188} WARNING -   File "/home/***/.local/lib/python3.12/site-packages/***/cli/commands/task_command.py", line 441, in task_run
    task_return_code = _run_task_by_selected_method(args, _dag, ti)
[2024-12-24T18:42:02.536+0000] {logging_mixin.py:188} WARNING -   File "/home/***/.local/lib/python3.12/site-packages/***/cli/commands/task_command.py", line 219, in _run_task_by_selected_method
    return _run_task_by_local_task_job(args, ti)
[2024-12-24T18:42:02.536+0000] {logging_mixin.py:188} WARNING -   File "/home/***/.local/lib/python3.12/site-packages/***/cli/commands/task_command.py", line 281, in _run_task_by_local_task_job
    ret = run_job(job=job_runner.job, execute_callable=job_runner._execute)
[2024-12-24T18:42:02.537+0000] {logging_mixin.py:188} WARNING -   File "/home/***/.local/lib/python3.12/site-packages/***/utils/session.py", line 79, in wrapper
    return func(*args, session=session, **kwargs)
[2024-12-24T18:42:02.537+0000] {logging_mixin.py:188} WARNING -   File "/home/***/.local/lib/python3.12/site-packages/***/jobs/job.py", line 402, in run_job
    return execute_job(job, execute_callable=execute_callable)
[2024-12-24T18:42:02.538+0000] {logging_mixin.py:188} WARNING -   File "/home/***/.local/lib/python3.12/site-packages/***/jobs/job.py", line 431, in execute_job
    ret = execute_callable()
[2024-12-24T18:42:02.538+0000] {logging_mixin.py:188} WARNING -   File "/home/***/.local/lib/python3.12/site-packages/***/jobs/local_task_job_runner.py", line 168, in _execute
    self.task_runner.start()
[2024-12-24T18:42:02.539+0000] {logging_mixin.py:188} WARNING -   File "/home/***/.local/lib/python3.12/site-packages/***/task/task_runner/standard_task_runner.py", line 51, in start
    self.process = self._start_by_fork()
[2024-12-24T18:42:02.539+0000] {logging_mixin.py:188} WARNING -   File "/home/***/.local/lib/python3.12/site-packages/***/task/task_runner/standard_task_runner.py", line 103, in _start_by_fork
    ret = args.func(args, dag=self.dag)
[2024-12-24T18:42:02.540+0000] {logging_mixin.py:188} WARNING -   File "/home/***/.local/lib/python3.12/site-packages/***/cli/cli_config.py", line 49, in command
    return func(*args, **kwargs)
[2024-12-24T18:42:02.540+0000] {logging_mixin.py:188} WARNING -   File "/home/***/.local/lib/python3.12/site-packages/***/utils/cli.py", line 114, in wrapper
    return f(*args, **kwargs)
[2024-12-24T18:42:02.541+0000] {logging_mixin.py:188} WARNING -   File "/home/***/.local/lib/python3.12/site-packages/***/cli/commands/task_command.py", line 441, in task_run
    task_return_code = _run_task_by_selected_method(args, _dag, ti)
[2024-12-24T18:42:02.541+0000] {logging_mixin.py:188} WARNING -   File "/home/***/.local/lib/python3.12/site-packages/***/cli/commands/task_command.py", line 221, in _run_task_by_selected_method
    return _run_raw_task(args, ti)
[2024-12-24T18:42:02.542+0000] {logging_mixin.py:188} WARNING -   File "/home/***/.local/lib/python3.12/site-packages/***/cli/commands/task_command.py", line 300, in _run_raw_task
    return ti._run_raw_task(
[2024-12-24T18:42:02.542+0000] {logging_mixin.py:188} WARNING -   File "/home/***/.local/lib/python3.12/site-packages/***/utils/session.py", line 79, in wrapper
    return func(*args, session=session, **kwargs)
[2024-12-24T18:42:02.543+0000] {logging_mixin.py:188} WARNING -   File "/home/***/.local/lib/python3.12/site-packages/***/models/taskinstance.py", line 2479, in _run_raw_task
    self._execute_task_with_callbacks(context, test_mode, session=session)
[2024-12-24T18:42:02.543+0000] {logging_mixin.py:188} WARNING -   File "/home/***/.local/lib/python3.12/site-packages/***/models/taskinstance.py", line 2676, in _execute_task_with_callbacks
    result = self._execute_task(context, task_orig)
[2024-12-24T18:42:02.543+0000] {logging_mixin.py:188} WARNING -   File "/home/***/.local/lib/python3.12/site-packages/***/models/taskinstance.py", line 2701, in _execute_task
    return _execute_task(self, context, task_orig)
[2024-12-24T18:42:02.544+0000] {logging_mixin.py:188} WARNING -   File "/home/***/.local/lib/python3.12/site-packages/***/models/taskinstance.py", line 465, in _execute_task
    result = _execute_callable(context=context, **execute_callable_kwargs)
[2024-12-24T18:42:02.544+0000] {logging_mixin.py:188} WARNING -   File "/home/***/.local/lib/python3.12/site-packages/***/models/taskinstance.py", line 432, in _execute_callable
    return execute_callable(context=context, **execute_callable_kwargs)
[2024-12-24T18:42:02.545+0000] {logging_mixin.py:188} WARNING -   File "/home/***/.local/lib/python3.12/site-packages/***/models/baseoperator.py", line 401, in wrapper
    return func(self, *args, **kwargs)
[2024-12-24T18:42:02.546+0000] {logging_mixin.py:188} WARNING -   File "/home/***/.local/lib/python3.12/site-packages/***/operators/python.py", line 235, in execute
    return_value = self.execute_callable()
[2024-12-24T18:42:02.546+0000] {logging_mixin.py:188} WARNING -   File "/home/***/.local/lib/python3.12/site-packages/***/operators/python.py", line 252, in execute_callable
    return self.python_callable(*self.op_args, **self.op_kwargs)
[2024-12-24T18:42:02.546+0000] {logging_mixin.py:188} WARNING -   File "/opt/***/dags/pipeline_batch_visualize.py", line 86, in start_pipeline
    logging.info("Start pipeline:", DATE)
[2024-12-24T18:42:02.547+0000] {logging_mixin.py:188} WARNING -   File "/usr/local/lib/python3.12/logging/__init__.py", line 2216, in info
    root.info(msg, *args, **kwargs)
[2024-12-24T18:42:02.548+0000] {logging_mixin.py:188} WARNING -   File "/usr/local/lib/python3.12/logging/__init__.py", line 1539, in info
    self._log(INFO, msg, args, **kwargs)
[2024-12-24T18:42:02.548+0000] {logging_mixin.py:188} WARNING -   File "/usr/local/lib/python3.12/logging/__init__.py", line 1684, in _log
    self.handle(record)
[2024-12-24T18:42:02.548+0000] {logging_mixin.py:188} WARNING -   File "/usr/local/lib/python3.12/logging/__init__.py", line 1700, in handle
    self.callHandlers(record)
[2024-12-24T18:42:02.549+0000] {logging_mixin.py:188} WARNING -   File "/usr/local/lib/python3.12/logging/__init__.py", line 1762, in callHandlers
    hdlr.handle(record)
[2024-12-24T18:42:02.549+0000] {logging_mixin.py:188} WARNING -   File "/usr/local/lib/python3.12/logging/__init__.py", line 1028, in handle
    self.emit(record)
[2024-12-24T18:42:02.550+0000] {logging_mixin.py:188} WARNING -   File "/home/***/.local/lib/python3.12/site-packages/***/utils/log/file_task_handler.py", line 248, in emit
    self.handler.emit(record)
[2024-12-24T18:42:02.550+0000] {logging_mixin.py:188} WARNING - Message: 'Start pipeline:'
Arguments: ('2024-01-02',)
[2024-12-24T18:42:02.551+0000] {logging_mixin.py:188} WARNING - --- Logging error ---
[2024-12-24T18:42:02.551+0000] {logging_mixin.py:188} WARNING - Traceback (most recent call last):
[2024-12-24T18:42:02.552+0000] {logging_mixin.py:188} WARNING -   File "/usr/local/lib/python3.12/logging/__init__.py", line 1160, in emit
    msg = self.format(record)
          ^^^^^^^^^^^^^^^^^^^
[2024-12-24T18:42:02.553+0000] {logging_mixin.py:188} WARNING -   File "/usr/local/lib/python3.12/logging/__init__.py", line 999, in format
    return fmt.format(record)
           ^^^^^^^^^^^^^^^^^^
[2024-12-24T18:42:02.553+0000] {logging_mixin.py:188} WARNING -   File "/usr/local/lib/python3.12/logging/__init__.py", line 703, in format
    record.message = record.getMessage()
                     ^^^^^^^^^^^^^^^^^^^
[2024-12-24T18:42:02.554+0000] {logging_mixin.py:188} WARNING -   File "/usr/local/lib/python3.12/logging/__init__.py", line 392, in getMessage
    msg = msg % self.args
          ~~~~^~~~~~~~~~~
[2024-12-24T18:42:02.555+0000] {logging_mixin.py:188} WARNING - TypeError: not all arguments converted during string formatting
[2024-12-24T18:42:02.555+0000] {logging_mixin.py:188} WARNING - Call stack:
[2024-12-24T18:42:02.558+0000] {logging_mixin.py:188} WARNING -   File "/home/***/.local/bin/***", line 8, in <module>
    sys.exit(main())
[2024-12-24T18:42:02.558+0000] {logging_mixin.py:188} WARNING -   File "/home/***/.local/lib/python3.12/site-packages/***/__main__.py", line 58, in main
    args.func(args)
[2024-12-24T18:42:02.559+0000] {logging_mixin.py:188} WARNING -   File "/home/***/.local/lib/python3.12/site-packages/***/cli/cli_config.py", line 49, in command
    return func(*args, **kwargs)
[2024-12-24T18:42:02.559+0000] {logging_mixin.py:188} WARNING -   File "/home/***/.local/lib/python3.12/site-packages/***/utils/cli.py", line 114, in wrapper
    return f(*args, **kwargs)
[2024-12-24T18:42:02.560+0000] {logging_mixin.py:188} WARNING -   File "/home/***/.local/lib/python3.12/site-packages/***/utils/providers_configuration_loader.py", line 55, in wrapped_function
    return func(*args, **kwargs)
[2024-12-24T18:42:02.560+0000] {logging_mixin.py:188} WARNING -   File "/home/***/.local/lib/python3.12/site-packages/***/cli/commands/scheduler_command.py", line 58, in scheduler
    run_command_with_daemon_option(
[2024-12-24T18:42:02.561+0000] {logging_mixin.py:188} WARNING -   File "/home/***/.local/lib/python3.12/site-packages/***/cli/commands/daemon_utils.py", line 85, in run_command_with_daemon_option
    callback()
[2024-12-24T18:42:02.561+0000] {logging_mixin.py:188} WARNING -   File "/home/***/.local/lib/python3.12/site-packages/***/cli/commands/scheduler_command.py", line 61, in <lambda>
    callback=lambda: _run_scheduler_job(args),
[2024-12-24T18:42:02.562+0000] {logging_mixin.py:188} WARNING -   File "/home/***/.local/lib/python3.12/site-packages/***/cli/commands/scheduler_command.py", line 49, in _run_scheduler_job
    run_job(job=job_runner.job, execute_callable=job_runner._execute)
[2024-12-24T18:42:02.563+0000] {logging_mixin.py:188} WARNING -   File "/home/***/.local/lib/python3.12/site-packages/***/utils/session.py", line 79, in wrapper
    return func(*args, session=session, **kwargs)
[2024-12-24T18:42:02.563+0000] {logging_mixin.py:188} WARNING -   File "/home/***/.local/lib/python3.12/site-packages/***/jobs/job.py", line 402, in run_job
    return execute_job(job, execute_callable=execute_callable)
[2024-12-24T18:42:02.563+0000] {logging_mixin.py:188} WARNING -   File "/home/***/.local/lib/python3.12/site-packages/***/jobs/job.py", line 431, in execute_job
    ret = execute_callable()
[2024-12-24T18:42:02.564+0000] {logging_mixin.py:188} WARNING -   File "/home/***/.local/lib/python3.12/site-packages/***/jobs/scheduler_job_runner.py", line 834, in _execute
    self.job.executor.start()
[2024-12-24T18:42:02.565+0000] {logging_mixin.py:188} WARNING -   File "/home/***/.local/lib/python3.12/site-packages/***/executors/local_executor.py", line 373, in start
    self.impl.start()
[2024-12-24T18:42:02.566+0000] {logging_mixin.py:188} WARNING -   File "/home/***/.local/lib/python3.12/site-packages/***/executors/local_executor.py", line 312, in start
    worker.start()
[2024-12-24T18:42:02.566+0000] {logging_mixin.py:188} WARNING -   File "/usr/local/lib/python3.12/multiprocessing/process.py", line 121, in start
    self._popen = self._Popen(self)
[2024-12-24T18:42:02.567+0000] {logging_mixin.py:188} WARNING -   File "/usr/local/lib/python3.12/multiprocessing/context.py", line 224, in _Popen
    return _default_context.get_context().Process._Popen(process_obj)
[2024-12-24T18:42:02.567+0000] {logging_mixin.py:188} WARNING -   File "/usr/local/lib/python3.12/multiprocessing/context.py", line 282, in _Popen
    return Popen(process_obj)
[2024-12-24T18:42:02.568+0000] {logging_mixin.py:188} WARNING -   File "/usr/local/lib/python3.12/multiprocessing/popen_fork.py", line 19, in __init__
    self._launch(process_obj)
[2024-12-24T18:42:02.568+0000] {logging_mixin.py:188} WARNING -   File "/usr/local/lib/python3.12/multiprocessing/popen_fork.py", line 71, in _launch
    code = process_obj._bootstrap(parent_sentinel=child_r)
[2024-12-24T18:42:02.568+0000] {logging_mixin.py:188} WARNING -   File "/usr/local/lib/python3.12/multiprocessing/process.py", line 314, in _bootstrap
    self.run()
[2024-12-24T18:42:02.569+0000] {logging_mixin.py:188} WARNING -   File "/home/***/.local/lib/python3.12/site-packages/***/executors/local_executor.py", line 78, in run
    return super().run()
[2024-12-24T18:42:02.569+0000] {logging_mixin.py:188} WARNING -   File "/usr/local/lib/python3.12/multiprocessing/process.py", line 108, in run
    self._target(*self._args, **self._kwargs)
[2024-12-24T18:42:02.570+0000] {logging_mixin.py:188} WARNING -   File "/home/***/.local/lib/python3.12/site-packages/***/executors/local_executor.py", line 202, in do_work
    self.execute_work(key=key, command=command)
[2024-12-24T18:42:02.571+0000] {logging_mixin.py:188} WARNING -   File "/home/***/.local/lib/python3.12/site-packages/***/executors/local_executor.py", line 95, in execute_work
    state = self._execute_work_in_fork(command)
[2024-12-24T18:42:02.572+0000] {logging_mixin.py:188} WARNING -   File "/home/***/.local/lib/python3.12/site-packages/***/executors/local_executor.py", line 135, in _execute_work_in_fork
    args.func(args)
[2024-12-24T18:42:02.573+0000] {logging_mixin.py:188} WARNING -   File "/home/***/.local/lib/python3.12/site-packages/***/cli/cli_config.py", line 49, in command
    return func(*args, **kwargs)
[2024-12-24T18:42:02.573+0000] {logging_mixin.py:188} WARNING -   File "/home/***/.local/lib/python3.12/site-packages/***/utils/cli.py", line 114, in wrapper
    return f(*args, **kwargs)
[2024-12-24T18:42:02.574+0000] {logging_mixin.py:188} WARNING -   File "/home/***/.local/lib/python3.12/site-packages/***/cli/commands/task_command.py", line 441, in task_run
    task_return_code = _run_task_by_selected_method(args, _dag, ti)
[2024-12-24T18:42:02.574+0000] {logging_mixin.py:188} WARNING -   File "/home/***/.local/lib/python3.12/site-packages/***/cli/commands/task_command.py", line 219, in _run_task_by_selected_method
    return _run_task_by_local_task_job(args, ti)
[2024-12-24T18:42:02.575+0000] {logging_mixin.py:188} WARNING -   File "/home/***/.local/lib/python3.12/site-packages/***/cli/commands/task_command.py", line 281, in _run_task_by_local_task_job
    ret = run_job(job=job_runner.job, execute_callable=job_runner._execute)
[2024-12-24T18:42:02.575+0000] {logging_mixin.py:188} WARNING -   File "/home/***/.local/lib/python3.12/site-packages/***/utils/session.py", line 79, in wrapper
    return func(*args, session=session, **kwargs)
[2024-12-24T18:42:02.575+0000] {logging_mixin.py:188} WARNING -   File "/home/***/.local/lib/python3.12/site-packages/***/jobs/job.py", line 402, in run_job
    return execute_job(job, execute_callable=execute_callable)
[2024-12-24T18:42:02.576+0000] {logging_mixin.py:188} WARNING -   File "/home/***/.local/lib/python3.12/site-packages/***/jobs/job.py", line 431, in execute_job
    ret = execute_callable()
[2024-12-24T18:42:02.576+0000] {logging_mixin.py:188} WARNING -   File "/home/***/.local/lib/python3.12/site-packages/***/jobs/local_task_job_runner.py", line 168, in _execute
    self.task_runner.start()
[2024-12-24T18:42:02.577+0000] {logging_mixin.py:188} WARNING -   File "/home/***/.local/lib/python3.12/site-packages/***/task/task_runner/standard_task_runner.py", line 51, in start
    self.process = self._start_by_fork()
[2024-12-24T18:42:02.578+0000] {logging_mixin.py:188} WARNING -   File "/home/***/.local/lib/python3.12/site-packages/***/task/task_runner/standard_task_runner.py", line 103, in _start_by_fork
    ret = args.func(args, dag=self.dag)
[2024-12-24T18:42:02.578+0000] {logging_mixin.py:188} WARNING -   File "/home/***/.local/lib/python3.12/site-packages/***/cli/cli_config.py", line 49, in command
    return func(*args, **kwargs)
[2024-12-24T18:42:02.579+0000] {logging_mixin.py:188} WARNING -   File "/home/***/.local/lib/python3.12/site-packages/***/utils/cli.py", line 114, in wrapper
    return f(*args, **kwargs)
[2024-12-24T18:42:02.580+0000] {logging_mixin.py:188} WARNING -   File "/home/***/.local/lib/python3.12/site-packages/***/cli/commands/task_command.py", line 441, in task_run
    task_return_code = _run_task_by_selected_method(args, _dag, ti)
[2024-12-24T18:42:02.581+0000] {logging_mixin.py:188} WARNING -   File "/home/***/.local/lib/python3.12/site-packages/***/cli/commands/task_command.py", line 221, in _run_task_by_selected_method
    return _run_raw_task(args, ti)
[2024-12-24T18:42:02.581+0000] {logging_mixin.py:188} WARNING -   File "/home/***/.local/lib/python3.12/site-packages/***/cli/commands/task_command.py", line 300, in _run_raw_task
    return ti._run_raw_task(
[2024-12-24T18:42:02.582+0000] {logging_mixin.py:188} WARNING -   File "/home/***/.local/lib/python3.12/site-packages/***/utils/session.py", line 79, in wrapper
    return func(*args, session=session, **kwargs)
[2024-12-24T18:42:02.583+0000] {logging_mixin.py:188} WARNING -   File "/home/***/.local/lib/python3.12/site-packages/***/models/taskinstance.py", line 2479, in _run_raw_task
    self._execute_task_with_callbacks(context, test_mode, session=session)
[2024-12-24T18:42:02.583+0000] {logging_mixin.py:188} WARNING -   File "/home/***/.local/lib/python3.12/site-packages/***/models/taskinstance.py", line 2676, in _execute_task_with_callbacks
    result = self._execute_task(context, task_orig)
[2024-12-24T18:42:02.584+0000] {logging_mixin.py:188} WARNING -   File "/home/***/.local/lib/python3.12/site-packages/***/models/taskinstance.py", line 2701, in _execute_task
    return _execute_task(self, context, task_orig)
[2024-12-24T18:42:02.585+0000] {logging_mixin.py:188} WARNING -   File "/home/***/.local/lib/python3.12/site-packages/***/models/taskinstance.py", line 465, in _execute_task
    result = _execute_callable(context=context, **execute_callable_kwargs)
[2024-12-24T18:42:02.585+0000] {logging_mixin.py:188} WARNING -   File "/home/***/.local/lib/python3.12/site-packages/***/models/taskinstance.py", line 432, in _execute_callable
    return execute_callable(context=context, **execute_callable_kwargs)
[2024-12-24T18:42:02.586+0000] {logging_mixin.py:188} WARNING -   File "/home/***/.local/lib/python3.12/site-packages/***/models/baseoperator.py", line 401, in wrapper
    return func(self, *args, **kwargs)
[2024-12-24T18:42:02.586+0000] {logging_mixin.py:188} WARNING -   File "/home/***/.local/lib/python3.12/site-packages/***/operators/python.py", line 235, in execute
    return_value = self.execute_callable()
[2024-12-24T18:42:02.587+0000] {logging_mixin.py:188} WARNING -   File "/home/***/.local/lib/python3.12/site-packages/***/operators/python.py", line 252, in execute_callable
    return self.python_callable(*self.op_args, **self.op_kwargs)
[2024-12-24T18:42:02.587+0000] {logging_mixin.py:188} WARNING -   File "/opt/***/dags/pipeline_batch_visualize.py", line 87, in start_pipeline
    logging.info("Args raw to processed:", args_raw_to_processed)
[2024-12-24T18:42:02.588+0000] {logging_mixin.py:188} WARNING -   File "/usr/local/lib/python3.12/logging/__init__.py", line 2216, in info
    root.info(msg, *args, **kwargs)
[2024-12-24T18:42:02.589+0000] {logging_mixin.py:188} WARNING -   File "/usr/local/lib/python3.12/logging/__init__.py", line 1539, in info
    self._log(INFO, msg, args, **kwargs)
[2024-12-24T18:42:02.589+0000] {logging_mixin.py:188} WARNING -   File "/usr/local/lib/python3.12/logging/__init__.py", line 1684, in _log
    self.handle(record)
[2024-12-24T18:42:02.590+0000] {logging_mixin.py:188} WARNING -   File "/usr/local/lib/python3.12/logging/__init__.py", line 1700, in handle
    self.callHandlers(record)
[2024-12-24T18:42:02.590+0000] {logging_mixin.py:188} WARNING -   File "/usr/local/lib/python3.12/logging/__init__.py", line 1762, in callHandlers
    hdlr.handle(record)
[2024-12-24T18:42:02.591+0000] {logging_mixin.py:188} WARNING -   File "/usr/local/lib/python3.12/logging/__init__.py", line 1028, in handle
    self.emit(record)
[2024-12-24T18:42:02.591+0000] {logging_mixin.py:188} WARNING -   File "/home/***/.local/lib/python3.12/site-packages/***/utils/log/file_task_handler.py", line 248, in emit
    self.handler.emit(record)
[2024-12-24T18:42:02.592+0000] {logging_mixin.py:188} WARNING - Message: 'Args raw to processed:'
Arguments: (Config(minio_access_key='Xs27nx9M4HgPQ5PXZiUE', minio_secret_key='8iifKZlUZh1NRbepsISUMdg1CxlaIC6OSPQk5X59', endpoint_url='192.168.1.12:9000', jars_dir='/opt/***/jars', taxi_lookup_path='s3a://raw/taxi_lookup.csv', num_output_files=1, green_path_src='s3a://raw/cdc_db/2024/01/02/data', yellow_path_src='s3a://raw/yellow/2024/01/02.parquet', green_path_dist='s3a://processed/data/green/2024/01/02', yellow_path_dist='s3a://processed/data/yellow/2024/01/02'),)
[2024-12-24T18:42:02.593+0000] {logging_mixin.py:188} WARNING - --- Logging error ---
[2024-12-24T18:42:02.594+0000] {logging_mixin.py:188} WARNING - Traceback (most recent call last):
[2024-12-24T18:42:02.595+0000] {logging_mixin.py:188} WARNING -   File "/usr/local/lib/python3.12/logging/__init__.py", line 1160, in emit
    msg = self.format(record)
          ^^^^^^^^^^^^^^^^^^^
[2024-12-24T18:42:02.596+0000] {logging_mixin.py:188} WARNING -   File "/usr/local/lib/python3.12/logging/__init__.py", line 999, in format
    return fmt.format(record)
           ^^^^^^^^^^^^^^^^^^
[2024-12-24T18:42:02.596+0000] {logging_mixin.py:188} WARNING -   File "/usr/local/lib/python3.12/logging/__init__.py", line 703, in format
    record.message = record.getMessage()
                     ^^^^^^^^^^^^^^^^^^^
[2024-12-24T18:42:02.597+0000] {logging_mixin.py:188} WARNING -   File "/usr/local/lib/python3.12/logging/__init__.py", line 392, in getMessage
    msg = msg % self.args
          ~~~~^~~~~~~~~~~
[2024-12-24T18:42:02.598+0000] {logging_mixin.py:188} WARNING - TypeError: not all arguments converted during string formatting
[2024-12-24T18:42:02.598+0000] {logging_mixin.py:188} WARNING - Call stack:
[2024-12-24T18:42:02.600+0000] {logging_mixin.py:188} WARNING -   File "/home/***/.local/bin/***", line 8, in <module>
    sys.exit(main())
[2024-12-24T18:42:02.601+0000] {logging_mixin.py:188} WARNING -   File "/home/***/.local/lib/python3.12/site-packages/***/__main__.py", line 58, in main
    args.func(args)
[2024-12-24T18:42:02.602+0000] {logging_mixin.py:188} WARNING -   File "/home/***/.local/lib/python3.12/site-packages/***/cli/cli_config.py", line 49, in command
    return func(*args, **kwargs)
[2024-12-24T18:42:02.603+0000] {logging_mixin.py:188} WARNING -   File "/home/***/.local/lib/python3.12/site-packages/***/utils/cli.py", line 114, in wrapper
    return f(*args, **kwargs)
[2024-12-24T18:42:02.603+0000] {logging_mixin.py:188} WARNING -   File "/home/***/.local/lib/python3.12/site-packages/***/utils/providers_configuration_loader.py", line 55, in wrapped_function
    return func(*args, **kwargs)
[2024-12-24T18:42:02.604+0000] {logging_mixin.py:188} WARNING -   File "/home/***/.local/lib/python3.12/site-packages/***/cli/commands/scheduler_command.py", line 58, in scheduler
    run_command_with_daemon_option(
[2024-12-24T18:42:02.605+0000] {logging_mixin.py:188} WARNING -   File "/home/***/.local/lib/python3.12/site-packages/***/cli/commands/daemon_utils.py", line 85, in run_command_with_daemon_option
    callback()
[2024-12-24T18:42:02.606+0000] {logging_mixin.py:188} WARNING -   File "/home/***/.local/lib/python3.12/site-packages/***/cli/commands/scheduler_command.py", line 61, in <lambda>
    callback=lambda: _run_scheduler_job(args),
[2024-12-24T18:42:02.607+0000] {logging_mixin.py:188} WARNING -   File "/home/***/.local/lib/python3.12/site-packages/***/cli/commands/scheduler_command.py", line 49, in _run_scheduler_job
    run_job(job=job_runner.job, execute_callable=job_runner._execute)
[2024-12-24T18:42:02.608+0000] {logging_mixin.py:188} WARNING -   File "/home/***/.local/lib/python3.12/site-packages/***/utils/session.py", line 79, in wrapper
    return func(*args, session=session, **kwargs)
[2024-12-24T18:42:02.608+0000] {logging_mixin.py:188} WARNING -   File "/home/***/.local/lib/python3.12/site-packages/***/jobs/job.py", line 402, in run_job
    return execute_job(job, execute_callable=execute_callable)
[2024-12-24T18:42:02.609+0000] {logging_mixin.py:188} WARNING -   File "/home/***/.local/lib/python3.12/site-packages/***/jobs/job.py", line 431, in execute_job
    ret = execute_callable()
[2024-12-24T18:42:02.610+0000] {logging_mixin.py:188} WARNING -   File "/home/***/.local/lib/python3.12/site-packages/***/jobs/scheduler_job_runner.py", line 834, in _execute
    self.job.executor.start()
[2024-12-24T18:42:02.611+0000] {logging_mixin.py:188} WARNING -   File "/home/***/.local/lib/python3.12/site-packages/***/executors/local_executor.py", line 373, in start
    self.impl.start()
[2024-12-24T18:42:02.611+0000] {logging_mixin.py:188} WARNING -   File "/home/***/.local/lib/python3.12/site-packages/***/executors/local_executor.py", line 312, in start
    worker.start()
[2024-12-24T18:42:02.612+0000] {logging_mixin.py:188} WARNING -   File "/usr/local/lib/python3.12/multiprocessing/process.py", line 121, in start
    self._popen = self._Popen(self)
[2024-12-24T18:42:02.613+0000] {logging_mixin.py:188} WARNING -   File "/usr/local/lib/python3.12/multiprocessing/context.py", line 224, in _Popen
    return _default_context.get_context().Process._Popen(process_obj)
[2024-12-24T18:42:02.613+0000] {logging_mixin.py:188} WARNING -   File "/usr/local/lib/python3.12/multiprocessing/context.py", line 282, in _Popen
    return Popen(process_obj)
[2024-12-24T18:42:02.614+0000] {logging_mixin.py:188} WARNING -   File "/usr/local/lib/python3.12/multiprocessing/popen_fork.py", line 19, in __init__
    self._launch(process_obj)
[2024-12-24T18:42:02.615+0000] {logging_mixin.py:188} WARNING -   File "/usr/local/lib/python3.12/multiprocessing/popen_fork.py", line 71, in _launch
    code = process_obj._bootstrap(parent_sentinel=child_r)
[2024-12-24T18:42:02.615+0000] {logging_mixin.py:188} WARNING -   File "/usr/local/lib/python3.12/multiprocessing/process.py", line 314, in _bootstrap
    self.run()
[2024-12-24T18:42:02.616+0000] {logging_mixin.py:188} WARNING -   File "/home/***/.local/lib/python3.12/site-packages/***/executors/local_executor.py", line 78, in run
    return super().run()
[2024-12-24T18:42:02.617+0000] {logging_mixin.py:188} WARNING -   File "/usr/local/lib/python3.12/multiprocessing/process.py", line 108, in run
    self._target(*self._args, **self._kwargs)
[2024-12-24T18:42:02.618+0000] {logging_mixin.py:188} WARNING -   File "/home/***/.local/lib/python3.12/site-packages/***/executors/local_executor.py", line 202, in do_work
    self.execute_work(key=key, command=command)
[2024-12-24T18:42:02.618+0000] {logging_mixin.py:188} WARNING -   File "/home/***/.local/lib/python3.12/site-packages/***/executors/local_executor.py", line 95, in execute_work
    state = self._execute_work_in_fork(command)
[2024-12-24T18:42:02.619+0000] {logging_mixin.py:188} WARNING -   File "/home/***/.local/lib/python3.12/site-packages/***/executors/local_executor.py", line 135, in _execute_work_in_fork
    args.func(args)
[2024-12-24T18:42:02.620+0000] {logging_mixin.py:188} WARNING -   File "/home/***/.local/lib/python3.12/site-packages/***/cli/cli_config.py", line 49, in command
    return func(*args, **kwargs)
[2024-12-24T18:42:02.621+0000] {logging_mixin.py:188} WARNING -   File "/home/***/.local/lib/python3.12/site-packages/***/utils/cli.py", line 114, in wrapper
    return f(*args, **kwargs)
[2024-12-24T18:42:02.622+0000] {logging_mixin.py:188} WARNING -   File "/home/***/.local/lib/python3.12/site-packages/***/cli/commands/task_command.py", line 441, in task_run
    task_return_code = _run_task_by_selected_method(args, _dag, ti)
[2024-12-24T18:42:02.622+0000] {logging_mixin.py:188} WARNING -   File "/home/***/.local/lib/python3.12/site-packages/***/cli/commands/task_command.py", line 219, in _run_task_by_selected_method
    return _run_task_by_local_task_job(args, ti)
[2024-12-24T18:42:02.623+0000] {logging_mixin.py:188} WARNING -   File "/home/***/.local/lib/python3.12/site-packages/***/cli/commands/task_command.py", line 281, in _run_task_by_local_task_job
    ret = run_job(job=job_runner.job, execute_callable=job_runner._execute)
[2024-12-24T18:42:02.624+0000] {logging_mixin.py:188} WARNING -   File "/home/***/.local/lib/python3.12/site-packages/***/utils/session.py", line 79, in wrapper
    return func(*args, session=session, **kwargs)
[2024-12-24T18:42:02.625+0000] {logging_mixin.py:188} WARNING -   File "/home/***/.local/lib/python3.12/site-packages/***/jobs/job.py", line 402, in run_job
    return execute_job(job, execute_callable=execute_callable)
[2024-12-24T18:42:02.626+0000] {logging_mixin.py:188} WARNING -   File "/home/***/.local/lib/python3.12/site-packages/***/jobs/job.py", line 431, in execute_job
    ret = execute_callable()
[2024-12-24T18:42:02.626+0000] {logging_mixin.py:188} WARNING -   File "/home/***/.local/lib/python3.12/site-packages/***/jobs/local_task_job_runner.py", line 168, in _execute
    self.task_runner.start()
[2024-12-24T18:42:02.627+0000] {logging_mixin.py:188} WARNING -   File "/home/***/.local/lib/python3.12/site-packages/***/task/task_runner/standard_task_runner.py", line 51, in start
    self.process = self._start_by_fork()
[2024-12-24T18:42:02.627+0000] {logging_mixin.py:188} WARNING -   File "/home/***/.local/lib/python3.12/site-packages/***/task/task_runner/standard_task_runner.py", line 103, in _start_by_fork
    ret = args.func(args, dag=self.dag)
[2024-12-24T18:42:02.628+0000] {logging_mixin.py:188} WARNING -   File "/home/***/.local/lib/python3.12/site-packages/***/cli/cli_config.py", line 49, in command
    return func(*args, **kwargs)
[2024-12-24T18:42:02.628+0000] {logging_mixin.py:188} WARNING -   File "/home/***/.local/lib/python3.12/site-packages/***/utils/cli.py", line 114, in wrapper
    return f(*args, **kwargs)
[2024-12-24T18:42:02.629+0000] {logging_mixin.py:188} WARNING -   File "/home/***/.local/lib/python3.12/site-packages/***/cli/commands/task_command.py", line 441, in task_run
    task_return_code = _run_task_by_selected_method(args, _dag, ti)
[2024-12-24T18:42:02.629+0000] {logging_mixin.py:188} WARNING -   File "/home/***/.local/lib/python3.12/site-packages/***/cli/commands/task_command.py", line 221, in _run_task_by_selected_method
    return _run_raw_task(args, ti)
[2024-12-24T18:42:02.630+0000] {logging_mixin.py:188} WARNING -   File "/home/***/.local/lib/python3.12/site-packages/***/cli/commands/task_command.py", line 300, in _run_raw_task
    return ti._run_raw_task(
[2024-12-24T18:42:02.630+0000] {logging_mixin.py:188} WARNING -   File "/home/***/.local/lib/python3.12/site-packages/***/utils/session.py", line 79, in wrapper
    return func(*args, session=session, **kwargs)
[2024-12-24T18:42:02.631+0000] {logging_mixin.py:188} WARNING -   File "/home/***/.local/lib/python3.12/site-packages/***/models/taskinstance.py", line 2479, in _run_raw_task
    self._execute_task_with_callbacks(context, test_mode, session=session)
[2024-12-24T18:42:02.631+0000] {logging_mixin.py:188} WARNING -   File "/home/***/.local/lib/python3.12/site-packages/***/models/taskinstance.py", line 2676, in _execute_task_with_callbacks
    result = self._execute_task(context, task_orig)
[2024-12-24T18:42:02.632+0000] {logging_mixin.py:188} WARNING -   File "/home/***/.local/lib/python3.12/site-packages/***/models/taskinstance.py", line 2701, in _execute_task
    return _execute_task(self, context, task_orig)
[2024-12-24T18:42:02.632+0000] {logging_mixin.py:188} WARNING -   File "/home/***/.local/lib/python3.12/site-packages/***/models/taskinstance.py", line 465, in _execute_task
    result = _execute_callable(context=context, **execute_callable_kwargs)
[2024-12-24T18:42:02.633+0000] {logging_mixin.py:188} WARNING -   File "/home/***/.local/lib/python3.12/site-packages/***/models/taskinstance.py", line 432, in _execute_callable
    return execute_callable(context=context, **execute_callable_kwargs)
[2024-12-24T18:42:02.633+0000] {logging_mixin.py:188} WARNING -   File "/home/***/.local/lib/python3.12/site-packages/***/models/baseoperator.py", line 401, in wrapper
    return func(self, *args, **kwargs)
[2024-12-24T18:42:02.634+0000] {logging_mixin.py:188} WARNING -   File "/home/***/.local/lib/python3.12/site-packages/***/operators/python.py", line 235, in execute
    return_value = self.execute_callable()
[2024-12-24T18:42:02.635+0000] {logging_mixin.py:188} WARNING -   File "/home/***/.local/lib/python3.12/site-packages/***/operators/python.py", line 252, in execute_callable
    return self.python_callable(*self.op_args, **self.op_kwargs)
[2024-12-24T18:42:02.636+0000] {logging_mixin.py:188} WARNING -   File "/opt/***/dags/pipeline_batch_visualize.py", line 88, in start_pipeline
    logging.info("Args spark to bigquery:", args_spark_to_bigquery)
[2024-12-24T18:42:02.636+0000] {logging_mixin.py:188} WARNING -   File "/usr/local/lib/python3.12/logging/__init__.py", line 2216, in info
    root.info(msg, *args, **kwargs)
[2024-12-24T18:42:02.637+0000] {logging_mixin.py:188} WARNING -   File "/usr/local/lib/python3.12/logging/__init__.py", line 1539, in info
    self._log(INFO, msg, args, **kwargs)
[2024-12-24T18:42:02.638+0000] {logging_mixin.py:188} WARNING -   File "/usr/local/lib/python3.12/logging/__init__.py", line 1684, in _log
    self.handle(record)
[2024-12-24T18:42:02.639+0000] {logging_mixin.py:188} WARNING -   File "/usr/local/lib/python3.12/logging/__init__.py", line 1700, in handle
    self.callHandlers(record)
[2024-12-24T18:42:02.639+0000] {logging_mixin.py:188} WARNING -   File "/usr/local/lib/python3.12/logging/__init__.py", line 1762, in callHandlers
    hdlr.handle(record)
[2024-12-24T18:42:02.640+0000] {logging_mixin.py:188} WARNING -   File "/usr/local/lib/python3.12/logging/__init__.py", line 1028, in handle
    self.emit(record)
[2024-12-24T18:42:02.641+0000] {logging_mixin.py:188} WARNING -   File "/home/***/.local/lib/python3.12/site-packages/***/utils/log/file_task_handler.py", line 248, in emit
    self.handler.emit(record)
[2024-12-24T18:42:02.641+0000] {logging_mixin.py:188} WARNING - Message: 'Args spark to bigquery:'
Arguments: (Config(max_memory='2g', minio_endpoint='192.168.1.12:9000', minio_access_key='Xs27nx9M4HgPQ5PXZiUE', minio_secret_key='8iifKZlUZh1NRbepsISUMdg1CxlaIC6OSPQk5X59', jars_dir='/opt/***/jars', bucket_name='processed', year='2024', month='01', day='02', date='2024-01-02', taxi_lookup_path='s3a://raw/taxi_lookup.csv', bq_project_id='bigdata-445102', bq_dataset_id='data_warehouse', path_auth_file='/opt/***/data/auth_gg_bigquery.json'),)
[2024-12-24T18:42:02.643+0000] {pipeline_batch_visualize.py:93} INFO - Path auth exist
[2024-12-24T18:42:02.644+0000] {pipeline_batch_visualize.py:94} INFO - /opt/***/data/auth_gg_bigquery.json
[2024-12-24T18:42:02.646+0000] {taskinstance.py:441} INFO - ::group::Post task execution logs
[2024-12-24T18:42:02.647+0000] {taskinstance.py:2905} ERROR - Task failed with exception
Traceback (most recent call last):
  File "/home/airflow/.local/lib/python3.12/site-packages/airflow/models/taskinstance.py", line 465, in _execute_task
    result = _execute_callable(context=context, **execute_callable_kwargs)
             ^^^^^^^^^^^^^^^^^^^^^^^^^^^^^^^^^^^^^^^^^^^^^^^^^^^^^^^^^^^^^
  File "/home/airflow/.local/lib/python3.12/site-packages/airflow/models/taskinstance.py", line 432, in _execute_callable
    return execute_callable(context=context, **execute_callable_kwargs)
           ^^^^^^^^^^^^^^^^^^^^^^^^^^^^^^^^^^^^^^^^^^^^^^^^^^^^^^^^^^^^
  File "/home/airflow/.local/lib/python3.12/site-packages/airflow/models/baseoperator.py", line 401, in wrapper
    return func(self, *args, **kwargs)
           ^^^^^^^^^^^^^^^^^^^^^^^^^^^
  File "/home/airflow/.local/lib/python3.12/site-packages/airflow/operators/python.py", line 235, in execute
    return_value = self.execute_callable()
                   ^^^^^^^^^^^^^^^^^^^^^^^
  File "/home/airflow/.local/lib/python3.12/site-packages/airflow/operators/python.py", line 252, in execute_callable
    return self.python_callable(*self.op_args, **self.op_kwargs)
           ^^^^^^^^^^^^^^^^^^^^^^^^^^^^^^^^^^^^^^^^^^^^^^^^^^^^^
  File "/opt/airflow/dags/pipeline_batch_visualize.py", line 95, in start_pipeline
    test_interact_with_windows()
  File "/opt/airflow/dags/pipeline_batch_visualize.py", line 80, in test_interact_with_windows
    with open(windows_path, "w") as f:
         ^^^^^^^^^^^^^^^^^^^^^^^
FileNotFoundError: [Errno 2] No such file or directory: '/mnt/e/test.txt'
[2024-12-24T18:42:02.658+0000] {taskinstance.py:1206} INFO - Marking task as FAILED. dag_id=pipeline_batch_visualize, task_id=start, run_id=manual__2024-12-24T18:42:00.591974+00:00, execution_date=20241224T184200, start_date=20241224T184202, end_date=20241224T184202
[2024-12-24T18:42:02.673+0000] {standard_task_runner.py:110} ERROR - Failed to execute job 338 for task start ([Errno 2] No such file or directory: '/mnt/e/test.txt'; 8748)
[2024-12-24T18:42:02.720+0000] {local_task_job_runner.py:240} INFO - Task exited with return code 1
[2024-12-24T18:42:02.744+0000] {taskinstance.py:3503} INFO - 0 downstream tasks scheduled from follow-on schedule check
[2024-12-24T18:42:02.750+0000] {local_task_job_runner.py:222} INFO - ::endgroup::
